Workbook

Sheet Entities
A1: entity | B1: listed_parent | C1: ticker | D1: exchange | E1: currency | F1: cross_check | G1: note
A2: 1911 Gold Corp | B2: 1911 Gold Corp | C2: AUMB.V | D2: TSXV | E2: CAD | F2: AUMBF
A3: Alamos Gold Inc. | B3: Alamos Gold Inc | C3: AGI.TO | D3: TSX | E3: CAD | F3: AGI
A4: Allied Gold South Africa | B4: Allied Gold Corp | C4: AAUC.TO | D4: TSX | E4: CAD | G4: Mapped to parent Allied Gold Corp (listed TSX 11 Sep 2023); specific SA entity unconfirmed
A5: AngloGold Ashanti Limited | B5: AngloGold Ashanti plc | C5: AU | D5: NYSE | E5: USD | F5: ANG.JO
A6: Argonaut Gold Corporate Account | B6: Argonaut Gold Inc | C6: AR.TO | D6: TSX | E6: CAD | F6: ARNGF | G6: Argonaut Gold was taken over by Alamos Gold on 12 Jul 2024
A7: Atlantic Mining NS Inc. | B7: St Barbara Ltd | C7: SBM.AX | D7: ASX | E7: AUD | G7: Nova Scotia operations; St Barbara bought Atlantic Gold on 19 Jul 2019
A8: B2Gold Corporation | B8: B2Gold Corp | C8: BTO.TO | D8: TSX | E8: CAD | F8: BTG
A9: Barkerville Gold Mines | B9: Osisko Gold Group Inc (formerly Osisko Development) | C9: OGG.V | D9: TSXV | E9: CAD | F9: OGG;OGG.TO;OR.TO | G9: Barkerville (BGM.V) until Osisko Gold Royalties bought it on 21 Nov 2019; moved into Osisko Development (listed late 2020), renamed Osisko Gold (OGG) Jul 2026
A10: Bralorne Gold Mines (Talisker Resources) | B10: Talisker Resources Ltd | C10: TSK.TO | D10: TSX | E10: CAD | F10: TSK.CN;TSKFF | G10: Subsidiary of Talisker since 16 Dec 2019
A11: Calibre Mining Corporation | B11: Calibre Mining Corp | C11: CXB.TO | D11: TSX | E11: CAD | F11: CXBMF | G11: Taken over by Equinox Gold on 17 Jun 2025
A12: Catalyst (Plutonic) Pty Ltd | B12: Catalyst Metals Ltd | C12: CYL.AX | D12: ASX | E12: AUD | G12: Plutonic mine; Catalyst bought Superior Gold on 30 Jun 2023
A13: Centerra Gold Inc. | B13: Centerra Gold Inc | C13: CG.TO | D13: TSX | E13: CAD | F13: CGAU
A14: Cerrado Gold - Minera Don Nicolas - Arge | B14: Cerrado Gold Inc | C14: CERT.V | D14: TSXV | E14: CAD | F14: CRDOF | G14: Subsidiary of Cerrado Gold since Mar 2020
A15: Eldorado | B15: Eldorado Gold Corp | C15: ELD.TO | D15: TSX | E15: CAD | F15: EGO
A16: Equinox Gold NAM - Leapfrog | B16: Equinox Gold Corp | C16: EQX.TO | D16: TSX | E16: CAD | F16: EQX | G16: Equinox Gold North America unit
A17: Fortuna Mining Corp | B17: Fortuna Mining Corp | C17: FVI.TO | D17: TSX | E17: CAD | F17: FSM
A18: Freda Rebecca Gold Mine | G18: No listing. Asa Resource Group (AIM) suspended 2017; mine now held by Kuvimba Mining House (Zimbabwe state)
A19: G Ex Australia Pty Ltd | G19: No listing found (likely Dynamics G-Ex Pty Ltd, a private geology supplier - unconfirmed)
A20: Genesis Minerals Limited | B20: Genesis Minerals Ltd | C20: GMD.AX | D20: ASX | E20: AUD
A21: Gold Fields Limited | B21: Gold Fields Ltd | C21: GFI | D21: NYSE | E21: USD | F21: GFI.JO
A22: Gold Road Resources | B22: Gold Road Resources Ltd | C22: GOR.AX | D22: ASX | E22: AUD | F22: ELKMF | G22: Taken over by Gold Fields; last traded 26 Sep 2025
A23: Golden Spur Resources Pty Ltd | B23: Bellevue Gold Ltd | C23: BGL.AX | D23: ASX | E23: AUD | G23: Subsidiary of Bellevue Gold
A24: Golden Star (Wassa) Ltd | B24: Chifeng Jilong Gold Mining Co Ltd | C24: 600988.SS | D24: SSE | E24: CNY | F24: 6693.HK | G24: Golden Star Resources (GSC.TO/GSS) owned Wassa until Chifeng bought it on 28 Jan 2022
A25: Grupo Minero Bacis S.A. de C.V. | G25: Private (Mexico)
A26: Harmony Gold Mining Company Ltd | B26: Harmony Gold Mining Co Ltd | C26: HMY | D26: NYSE | E26: USD | F26: HAR.JO
A27: Hellyer Gold Mines Pty Ltd | G27: No listing. Parent NQ Minerals (Aquis) went into administration Aug 2021; now privately owned
A28: Hummingbird Resources plc. | B28: Hummingbird Resources plc | C28: HUM.L | D28: LSE AIM | E28: GBp | G28: Taken private by Nioko Resources; last traded on AIM 28 Feb 2025
A29: IAMGOLD | B29: IAMGOLD Corp | C29: IMG.TO | D29: TSX | E29: CAD | F29: IAG
A30: JSC "AK ALTYNALMAS" | G30: Private (Kazakhstan); shares registered on KASE but not traded
A31: K92 Mining Ltd | B31: K92 Mining Inc | C31: KNT.TO | D31: TSX | E31: CAD | F31: KNTNF
A32: Kinross Gold Inc. | B32: Kinross Gold Corp | C32: K.TO | D32: TSX | E32: CAD | F32: KGC
A33: Lane Xang Minerals Limited (LXML) | B33: Chifeng Jilin Gold Mining Co Ltd | C33: 600988.SS | D33: SSE | E33: CNY | F33: 6693.HK | G33: Sepon mine; bought by Chifeng from MMG on 30 Nov 2018
A34: Mandalay Resources – Björkdalsgruvan AB | B34: Alkane Resources Ltd | C34: ALK.AX | D34: ASX | E34: AUD | F34: ALK.TO;MND.TO | G34: Mandalay Resources (MND.TO) owned Björkdal until its merger with Alkane on 5 Aug 2025
A35: McEwen Mining - Black Fox Mine | B35: McEwen Mining Inc | C35: MUX | D35: NYSE | E35: USD | F35: MUX.TO | G35: Black Fox bought by McEwen from Primero on 6 Oct 2017
A36: Mensin Gold Bibiani Limited | B36: Asante Gold Corp | C36: ASE.V | D36: TSXV | E36: CAD | F36: ASE.CN;ASGOF | G36: Subsidiary of Asante Gold since 19 Aug 2021 (bought from Resolute)
A37: Minera Las Cenizas S.A. | G37: Private (Chile)
A38: Mineros - Argentina | B38: Mineros SA | C38: MSA.TO | D38: TSX | E38: CAD | G38: Mineros SA (Colombia); TSX listing from 19 Nov 2021. Argentine Gualcamayo mine sold 2023
A39: Model Earth | G39: Private geology consultancy (Perth) - no listing (identity unconfirmed)
A40: Mt Weld Mining Pty Limited | B40: Lynas Rare Earths Ltd | C40: LYC.AX | D40: ASX | E40: AUD
...

Sheet Revenue
A1: ticker | B1: company | C1: currency | D1: fiscal year ends | E1: 2017 | F1: 2018 | G1: 2019 | H1: 2020 | I1: 2021 | J1: 2022 | K1: 2023 | L1: 2024 | M1: 2025 | N1: 2026
A2: 2259.HK | B2: Zijin Gold International Co Ltd | C2: USD | D2: 31 Dec | J2: 1817.98 | K2: 2262.36 | L2: 2989.93 | M2: 5383.48
A3: 600988.SS | B3: Chifeng Jilong Gold Mining Co Ltd | C3: CNY | D3: 31 Dec | I3: 3782.62 | J3: 6266.79 | K3: 7220.95 | L3: 9025.82 | M3: 12638.51
A4: AAUC.TO | B4: Allied Gold Corp | C4: USD | D4: 31 Dec | I4: 489.33 | J4: 669.55 | K4: 655.69 | L4: 730.38 | M4: 1331.82
A5: AGI.TO | B5: Alamos Gold Inc | C5: USD | D5: 31 Dec | I5: 823.6 | J5: 821.2 | K5: 1023.3 | L5: 1346.9 | M5: 1808.8
A6: ALK.AX | B6: Alkane Resources Ltd | C6: AUD | D6: 30 Jun | J6: 165.01 | K6: 190.53 | L6: 172.99 | M6: 262.36 | N6: 935.82
A7: AMRQ.L | B7: Amaroq Minerals Ltd | C7: CAD | D7: 31 Dec | I7: 0 | J7: 0 | K7: 0 | L7: 0
A8: AR.TO | B8: Argonaut Gold Inc
A9: ASE.V | B9: Asante Gold Corp | C9: USD | D9: 31 Dec | I9: 0 | J9: 205.99 | K9: 426.13 | L9: 458.88 | M9: 526.47
A10: AU | B10: AngloGold Ashanti plc | C10: USD | D10: 31 Dec | I10: 4029 | J10: 4501 | K10: 4582 | L10: 5793 | M10: 9893
A11: AUMB.V | B11: 1911 Gold Corp | C11: CAD | D11: 31 Dec | I11: 9.67 | J11: 5.88 | K11: 0.73 | L11: 0 | M11: 0
A12: BGL.AX | B12: Bellevue Gold Ltd | C12: AUD | D12: 30 Jun | L12: 298.41 | M12: 394.97 | N12: 576.26
A13: BTO.TO | B13: B2Gold Corp | C13: USD | D13: 31 Dec | I13: 1762.26 | J13: 1732.59 | K13: 1934.27 | L13: 1902.03 | M13: 3061.24
A14: CERT.V | B14: Cerrado Gold Inc | C14: USD | D14: 31 Dec | I14: 70.05 | J14: 90.36 | K14: 100.1 | L14: 116.17 | M14: 147.09
A15: CG.TO | B15: Centerra Gold Inc | C15: USD | D15: 31 Dec | I15: 900.14 | J15: 850.19 | K15: 1094.9 | L15: 1214.5 | M15: 1384.56
A16: CXB.TO | B16: Calibre Mining Corp | C16: USD | D16: 31 Dec | H16: 242.75 | I16: 328.13 | J16: 408.61 | K16: 561.7 | L16: 585.86
A17: CYL.AX | B17: Catalyst Metals Ltd | C17: AUD | D17: 30 Jun | J17: 63.33 | K17: 63.94 | L17: 241.95 | M17: 361.41 | N17: 631.94
A18: ELD.TO | B18: Eldorado Gold Corp | C18: USD | D18: 31 Dec | I18: 940.91 | J18: 871.98 | K18: 1008.5 | L18: 1322.58 | M18: 1818.86
A19: EQX.TO | B19: Equinox Gold Corp | C19: USD | D19: 31 Dec | I19: 1082.29 | J19: 952.2 | K19: 1088.19 | L19: 912.84 | M19: 1817.19
A20: FVI.TO | B20: Fortuna Mining Corp | C20: USD | D20: 31 Dec | I20: 599.85 | J20: 681.49 | K20: 842.43 | L20: 677.24 | M20: 947.06
A21: GFI | B21: Gold Fields Ltd | C21: USD | D21: 31 Dec | I21: 4195.2 | J21: 4286.7 | K21: 4500.7 | L21: 5201.6 | M21: 8751.3
A22: GMD.AX | B22: Genesis Minerals Ltd | C22: AUD | D22: 30 Jun | K22: 76.96 | L22: 438.59 | M22: 920.14 | N22: 1742.35
A23: GOR.AX | B23: Gold Road Resources Ltd | C23: AUD | D23: 31 Dec | H23: 294.65 | I23: 274.76 | J23: 382.94 | K23: 472.12 | L23: 527.96
A24: HMY | B24: Harmony Gold Mining Co Ltd | C24: ZAR | D24: 30 Jun | J24: 42645 | K24: 49275 | L24: 61379 | M24: 73896 | N24: 99238
A25: HUM.L | B25: Hummingbird Resources plc
A26: IAU.TO | B26: i-80 Gold Corp | C26: USD | D26: 31 Dec | J26: 36.96 | K26: 54.91 | L26: 50.34 | M26: 95.19
A27: IMG.TO | B27: IAMGOLD Corp | C27: USD | D27: 31 Dec | I27: 875.5 | J27: 958.8 | K27: 987.1 | L27: 1633 | M27: 2852.8
A28: K.TO | B28: Kinross Gold Corp | C28: USD | D28: 31 Dec | I28: 2599.6 | J28: 3455.1 | K28: 4239.7 | L28: 5148.8 | M28: 7051.1
A29: KNT.TO | B29: K92 Mining Inc | C29: USD | D29: 31 Dec | I29: 154.33 | J29: 188.19 | K29: 200.25 | L29: 350.62 | M29: 595.25
A30: LYC.AX | B30: Lynas Rare Earths Ltd | C30: AUD | D30: 30 Jun | J30: 920.01 | K30: 739.28 | L30: 463.29 | M30: 556.51 | N30: 977.95
A31: MSA.TO | B31: Mineros SA | C31: USD | D31: 31 Dec | I31: 496.25 | J31: 414.94 | K31: 447.29 | L31: 538.57 | M31: 799.67
A32: MUX | B32: McEwen Mining Inc | C32: USD | D32: 31 Dec | I32: 136.54 | J32: 110.42 | K32: 166.23 | L32: 174.48 | M32: 197.55
A33: NFGC.TO | B33: New Found Gold Corp | C33: CAD | D33: 31 Dec | J33: 0 | K33: 0 | L33: 0 | M33: 5.81
A34: OBM.AX | B34: Ora Banda Mining Ltd | C34: AUD | D34: 30 Jun | J34: 154.26 | K34: 135.89 | L34: 214.24 | M34: 404.29 | N34: 807.5
A35: OGC.TO | B35: OceanaGold Corp | C35: USD | D35: 31 Dec | I35: 744.7 | J35: 967.4 | K35: 1026.3 | L35: 1294 | M35: 1893.2
A36: OGG.V | B36: Osisko Gold Group Inc (formerly Osisko Development) | C36: CAD | D36: 31 Dec | I36: 7.66 | J36: 64.05 | K36: 31.62 | L36: 4.56 | M36: 35.48
A37: OLA.TO | B37: Orla Mining Ltd | C37: USD | D37: 31 Dec | I37: 4.12 | J37: 193.23 | K37: 233.64 | L37: 343.92 | M37: 1057.88
A38: PGM.V | B38: Pure Gold Mining Inc
A39: PNR.AX | B39: Pantoro Gold Ltd | C39: AUD | D39: 30 Jun | I39: 87.79 | J39: 73.52 | K39: 98.54 | L39: 229.43 | M39: 357.3
A40: PSAB.JK | B40: PT J Resources Asia Pasifik Tbk | C40: USD | D40: 31 Dec | I40: 237.15 | J40: 100.27 | K40: 170.15 | L40: 236.01 | M40: 288.75
...

Sheet Revenue USD
A1: ticker | B1: company | C1: currency | D1: fiscal year ends | E1: 2017 | F1: 2018 | G1: 2019 | H1: 2020 | I1: 2021 | J1: 2022 | K1: 2023 | L1: 2024 | M1: 2025 | N1: 2026
A2: 2259.HK | B2: Zijin Gold International Co Ltd | C2: USD | D2: 31 Dec | J2: =IF(OR('Revenue'!J2="",'FX rate used'!J2=""),"",'Revenue'!J2/'FX rate used'!J2) -> 1817.98 | K2: =IF(OR('Revenue'!K2="",'FX rate used'!K2=""),"",'Revenue'!K2/'FX rate used'!K2) -> 2262.36 | L2: =IF(OR('Revenue'!L2="",'FX rate used'!L2=""),"",'Revenue'!L2/'FX rate used'!L2) -> 2989.93 | M2: =IF(OR('Revenue'!M2="",'FX rate used'!M2=""),"",'Revenue'!M2/'FX rate used'!M2) -> 5383.48
A3: 600988.SS | B3: Chifeng Jilong Gold Mining Co Ltd | C3: USD | D3: 31 Dec | I3: =IF(OR('Revenue'!I3="",'FX rate used'!I3=""),"",'Revenue'!I3/'FX rate used'!I3) -> 586.4248 | J3: =IF(OR('Revenue'!J3="",'FX rate used'!J3=""),"",'Revenue'!J3/'FX rate used'!J3) -> 931.25968 | K3: =IF(OR('Revenue'!K3="",'FX rate used'!K3=""),"",'Revenue'!K3/'FX rate used'!K3) -> 1021.112 | L3: =IF(OR('Revenue'!L3="",'FX rate used'!L3=""),"",'Revenue'!L3/'FX rate used'!L3) -> 1255.9962 | M3: =IF(OR('Revenue'!M3="",'FX rate used'!M3=""),"",'Revenue'!M3/'FX rate used'!M3) -> 1758.5798
A4: AAUC.TO | B4: Allied Gold Corp | C4: USD | D4: 31 Dec | I4: =IF(OR('Revenue'!I4="",'FX rate used'!I4=""),"",'Revenue'!I4/'FX rate used'!I4) -> 489.33 | J4: =IF(OR('Revenue'!J4="",'FX rate used'!J4=""),"",'Revenue'!J4/'FX rate used'!J4) -> 669.55 | K4: =IF(OR('Revenue'!K4="",'FX rate used'!K4=""),"",'Revenue'!K4/'FX rate used'!K4) -> 655.69 | L4: =IF(OR('Revenue'!L4="",'FX rate used'!L4=""),"",'Revenue'!L4/'FX rate used'!L4) -> 730.38 | M4: =IF(OR('Revenue'!M4="",'FX rate used'!M4=""),"",'Revenue'!M4/'FX rate used'!M4) -> 1331.82
A5: AGI.TO | B5: Alamos Gold Inc | C5: USD | D5: 31 Dec | I5: =IF(OR('Revenue'!I5="",'FX rate used'!I5=""),"",'Revenue'!I5/'FX rate used'!I5) -> 823.6 | J5: =IF(OR('Revenue'!J5="",'FX rate used'!J5=""),"",'Revenue'!J5/'FX rate used'!J5) -> 821.2 | K5: =IF(OR('Revenue'!K5="",'FX rate used'!K5=""),"",'Revenue'!K5/'FX rate used'!K5) -> 1023.3 | L5: =IF(OR('Revenue'!L5="",'FX rate used'!L5=""),"",'Revenue'!L5/'FX rate used'!L5) -> 1346.9 | M5: =IF(OR('Revenue'!M5="",'FX rate used'!M5=""),"",'Revenue'!M5/'FX rate used'!M5) -> 1808.8
A6: ALK.AX | B6: Alkane Resources Ltd | C6: USD | D6: 30 Jun | J6: =IF(OR('Revenue'!J6="",'FX rate used'!J6=""),"",'Revenue'!J6/'FX rate used'!J6) -> 119.71734 | K6: =IF(OR('Revenue'!K6="",'FX rate used'!K6=""),"",'Revenue'!K6/'FX rate used'!K6) -> 128.19745 | L6: =IF(OR('Revenue'!L6="",'FX rate used'!L6=""),"",'Revenue'!L6/'FX rate used'!L6) -> 113.40974 | M6: =IF(OR('Revenue'!M6="",'FX rate used'!M6=""),"",'Revenue'!M6/'FX rate used'!M6) -> 169.88388 | N6: =IF(OR('Revenue'!N6="",'FX rate used'!N6=""),"",'Revenue'!N6/'FX rate used'!N6) -> 634.21001
A7: AMRQ.L | B7: Amaroq Minerals Ltd | C7: USD | D7: 31 Dec | I7: =IF(OR('Revenue'!I7="",'FX rate used'!I7=""),"",'Revenue'!I7/'FX rate used'!I7) -> 0 | J7: =IF(OR('Revenue'!J7="",'FX rate used'!J7=""),"",'Revenue'!J7/'FX rate used'!J7) -> 0 | K7: =IF(OR('Revenue'!K7="",'FX rate used'!K7=""),"",'Revenue'!K7/'FX rate used'!K7) -> 0 | L7: =IF(OR('Revenue'!L7="",'FX rate used'!L7=""),"",'Revenue'!L7/'FX rate used'!L7) -> 0
A8: AR.TO | B8: Argonaut Gold Inc | C8: USD
A9: ASE.V | B9: Asante Gold Corp | C9: USD | D9: 31 Dec | I9: =IF(OR('Revenue'!I9="",'FX rate used'!I9=""),"",'Revenue'!I9/'FX rate used'!I9) -> 0 | J9: =IF(OR('Revenue'!J9="",'FX rate used'!J9=""),"",'Revenue'!J9/'FX rate used'!J9) -> 205.99 | K9: =IF(OR('Revenue'!K9="",'FX rate used'!K9=""),"",'Revenue'!K9/'FX rate used'!K9) -> 426.13 | L9: =IF(OR('Revenue'!L9="",'FX rate used'!L9=""),"",'Revenue'!L9/'FX rate used'!L9) -> 458.88 | M9: =IF(OR('Revenue'!M9="",'FX rate used'!M9=""),"",'Revenue'!M9/'FX rate used'!M9) -> 526.47
A10: AU | B10: AngloGold Ashanti plc | C10: USD | D10: 31 Dec | I10: =IF(OR('Revenue'!I10="",'FX rate used'!I10=""),"",'Revenue'!I10/'FX rate used'!I10) -> 4029 | J10: =IF(OR('Revenue'!J10="",'FX rate used'!J10=""),"",'Revenue'!J10/'FX rate used'!J10) -> 4501 | K10: =IF(OR('Revenue'!K10="",'FX rate used'!K10=""),"",'Revenue'!K10/'FX rate used'!K10) -> 4582 | L10: =IF(OR('Revenue'!L10="",'FX rate used'!L10=""),"",'Revenue'!L10/'FX rate used'!L10) -> 5793 | M10: =IF(OR('Revenue'!M10="",'FX rate used'!M10=""),"",'Revenue'!M10/'FX rate used'!M10) -> 9893
A11: AUMB.V | B11: 1911 Gold Corp | C11: USD | D11: 31 Dec | I11: =IF(OR('Revenue'!I11="",'FX rate used'!I11=""),"",'Revenue'!I11/'FX rate used'!I11) -> 7.7145597 | J11: =IF(OR('Revenue'!J11="",'FX rate used'!J11=""),"",'Revenue'!J11/'FX rate used'!J11) -> 4.5183431 | K11: =IF(OR('Revenue'!K11="",'FX rate used'!K11=""),"",'Revenue'!K11/'FX rate used'!K11) -> 0.54096274 | L11: =IF(OR('Revenue'!L11="",'FX rate used'!L11=""),"",'Revenue'!L11/'FX rate used'!L11) -> 0 | M11: =IF(OR('Revenue'!M11="",'FX rate used'!M11=""),"",'Revenue'!M11/'FX rate used'!M11) -> 0
A12: BGL.AX | B12: Bellevue Gold Ltd | C12: USD | D12: 30 Jun | L12: =IF(OR('Revenue'!L12="",'FX rate used'!L12=""),"",'Revenue'!L12/'FX rate used'!L12) -> 195.63328 | M12: =IF(OR('Revenue'!M12="",'FX rate used'!M12=""),"",'Revenue'!M12/'FX rate used'!M12) -> 255.75178 | N12: =IF(OR('Revenue'!N12="",'FX rate used'!N12=""),"",'Revenue'!N12/'FX rate used'!N12) -> 390.53436
A13: BTO.TO | B13: B2Gold Corp | C13: USD | D13: 31 Dec | I13: =IF(OR('Revenue'!I13="",'FX rate used'!I13=""),"",'Revenue'!I13/'FX rate used'!I13) -> 1762.26 | J13: =IF(OR('Revenue'!J13="",'FX rate used'!J13=""),"",'Revenue'!J13/'FX rate used'!J13) -> 1732.59 | K13: =IF(OR('Revenue'!K13="",'FX rate used'!K13=""),"",'Revenue'!K13/'FX rate used'!K13) -> 1934.27 | L13: =IF(OR('Revenue'!L13="",'FX rate used'!L13=""),"",'Revenue'!L13/'FX rate used'!L13) -> 1902.03 | M13: =IF(OR('Revenue'!M13="",'FX rate used'!M13=""),"",'Revenue'!M13/'FX rate used'!M13) -> 3061.24
A14: CERT.V | B14: Cerrado Gold Inc | C14: USD | D14: 31 Dec | I14: =IF(OR('Revenue'!I14="",'FX rate used'!I14=""),"",'Revenue'!I14/'FX rate used'!I14) -> 70.05 | J14: =IF(OR('Revenue'!J14="",'FX rate used'!J14=""),"",'Revenue'!J14/'FX rate used'!J14) -> 90.36 | K14: =IF(OR('Revenue'!K14="",'FX rate used'!K14=""),"",'Revenue'!K14/'FX rate used'!K14) -> 100.1 | L14: =IF(OR('Revenue'!L14="",'FX rate used'!L14=""),"",'Revenue'!L14/'FX rate used'!L14) -> 116.17 | M14: =IF(OR('Revenue'!M14="",'FX rate used'!M14=""),"",'Revenue'!M14/'FX rate used'!M14) -> 147.09
A15: CG.TO | B15: Centerra Gold Inc | C15: USD | D15: 31 Dec | I15: =IF(OR('Revenue'!I15="",'FX rate used'!I15=""),"",'Revenue'!I15/'FX rate used'!I15) -> 900.14 | J15: =IF(OR('Revenue'!J15="",'FX rate used'!J15=""),"",'Revenue'!J15/'FX rate used'!J15) -> 850.19 | K15: =IF(OR('Revenue'!K15="",'FX rate used'!K15=""),"",'Revenue'!K15/'FX rate used'!K15) -> 1094.9 | L15: =IF(OR('Revenue'!L15="",'FX rate used'!L15=""),"",'Revenue'!L15/'FX rate used'!L15) -> 1214.5 | M15: =IF(OR('Revenue'!M15="",'FX rate used'!M15=""),"",'Revenue'!M15/'FX rate used'!M15) -> 1384.56
A16: CXB.TO | B16: Calibre Mining Corp | C16: USD | D16: 31 Dec | H16: =IF(OR('Revenue'!H16="",'FX rate used'!H16=""),"",'Revenue'!H16/'FX rate used'!H16) -> 242.75 | I16: =IF(OR('Revenue'!I16="",'FX rate used'!I16=""),"",'Revenue'!I16/'FX rate used'!I16) -> 328.13 | J16: =IF(OR('Revenue'!J16="",'FX rate used'!J16=""),"",'Revenue'!J16/'FX rate used'!J16) -> 408.61 | K16: =IF(OR('Revenue'!K16="",'FX rate used'!K16=""),"",'Revenue'!K16/'FX rate used'!K16) -> 561.7 | L16: =IF(OR('Revenue'!L16="",'FX rate used'!L16=""),"",'Revenue'!L16/'FX rate used'!L16) -> 585.86
A17: CYL.AX | B17: Catalyst Metals Ltd | C17: USD | D17: 30 Jun | J17: =IF(OR('Revenue'!J17="",'FX rate used'!J17=""),"",'Revenue'!J17/'FX rate used'!J17) -> 45.946907 | K17: =IF(OR('Revenue'!K17="",'FX rate used'!K17=""),"",'Revenue'!K17/'FX rate used'!K17) -> 43.021808 | L17: =IF(OR('Revenue'!L17="",'FX rate used'!L17=""),"",'Revenue'!L17/'FX rate used'!L17) -> 158.61892 | M17: =IF(OR('Revenue'!M17="",'FX rate used'!M17=""),"",'Revenue'!M17/'FX rate used'!M17) -> 234.02094 | N17: =IF(OR('Revenue'!N17="",'FX rate used'!N17=""),"",'Revenue'!N17/'FX rate used'!N17) -> 428.26898
A18: ELD.TO | B18: Eldorado Gold Corp | C18: USD | D18: 31 Dec | I18: =IF(OR('Revenue'!I18="",'FX rate used'!I18=""),"",'Revenue'!I18/'FX rate used'!I18) -> 940.91 | J18: =IF(OR('Revenue'!J18="",'FX rate used'!J18=""),"",'Revenue'!J18/'FX rate used'!J18) -> 871.98 | K18: =IF(OR('Revenue'!K18="",'FX rate used'!K18=""),"",'Revenue'!K18/'FX rate used'!K18) -> 1008.5 | L18: =IF(OR('Revenue'!L18="",'FX rate used'!L18=""),"",'Revenue'!L18/'FX rate used'!L18) -> 1322.58 | M18: =IF(OR('Revenue'!M18="",'FX rate used'!M18=""),"",'Revenue'!M18/'FX rate used'!M18) -> 1818.86
A19: EQX.TO | B19: Equinox Gold Corp | C19: USD | D19: 31 Dec | I19: =IF(OR('Revenue'!I19="",'FX rate used'!I19=""),"",'Revenue'!I19/'FX rate used'!I19) -> 1082.29 | J19: =IF(OR('Revenue'!J19="",'FX rate used'!J19=""),"",'Revenue'!J19/'FX rate used'!J19) -> 952.2 | K19: =IF(OR('Revenue'!K19="",'FX rate used'!K19=""),"",'Revenue'!K19/'FX rate used'!K19) -> 1088.19 | L19: =IF(OR('Revenue'!L19="",'FX rate used'!L19=""),"",'Revenue'!L19/'FX rate used'!L19) -> 912.84 | M19: =IF(OR('Revenue'!M19="",'FX rate used'!M19=""),"",'Revenue'!M19/'FX rate used'!M19) -> 1817.19
A20: FVI.TO | B20: Fortuna Mining Corp | C20: USD | D20: 31 Dec | I20: =IF(OR('Revenue'!I20="",'FX rate used'!I20=""),"",'Revenue'!I20/'FX rate used'!I20) -> 599.85 | J20: =IF(OR('Revenue'!J20="",'FX rate used'!J20=""),"",'Revenue'!J20/'FX rate used'!J20) -> 681.49 | K20: =IF(OR('Revenue'!K20="",'FX rate used'!K20=""),"",'Revenue'!K20/'FX rate used'!K20) -> 842.43 | L20: =IF(OR('Revenue'!L20="",'FX rate used'!L20=""),"",'Revenue'!L20/'FX rate used'!L20) -> 677.24 | M20: =IF(OR('Revenue'!M20="",'FX rate used'!M20=""),"",'Revenue'!M20/'FX rate used'!M20) -> 947.06
A21: GFI | B21: Gold Fields Ltd | C21: USD | D21: 31 Dec | I21: =IF(OR('Revenue'!I21="",'FX rate used'!I21=""),"",'Revenue'!I21/'FX rate used'!I21) -> 4195.2 | J21: =IF(OR('Revenue'!J21="",'FX rate used'!J21=""),"",'Revenue'!J21/'FX rate used'!J21) -> 4286.7 | K21: =IF(OR('Revenue'!K21="",'FX rate used'!K21=""),"",'Revenue'!K21/'FX rate used'!K21) -> 4500.7 | L21: =IF(OR('Revenue'!L21="",'FX rate used'!L21=""),"",'Revenue'!L21/'FX rate used'!L21) -> 5201.6 | M21: =IF(OR('Revenue'!M21="",'FX rate used'!M21=""),"",'Revenue'!M21/'FX rate used'!M21) -> 8751.3
A22: GMD.AX | B22: Genesis Minerals Ltd | C22: USD | D22: 30 Jun | K22: =IF(OR('Revenue'!K22="",'FX rate used'!K22=""),"",'Revenue'!K22/'FX rate used'!K22) -> 51.78227 | L22: =IF(OR('Revenue'!L22="",'FX rate used'!L22=""),"",'Revenue'!L22/'FX rate used'!L22) -> 287.53325 | M22: =IF(OR('Revenue'!M22="",'FX rate used'!M22=""),"",'Revenue'!M22/'FX rate used'!M22) -> 595.81092 | N22: =IF(OR('Revenue'!N22="",'FX rate used'!N22=""),"",'Revenue'!N22/'FX rate used'!N22) -> 1180.7995
A23: GOR.AX | B23: Gold Road Resources Ltd | C23: USD | D23: 31 Dec | H23: =IF(OR('Revenue'!H23="",'FX rate used'!H23=""),"",'Revenue'!H23/'FX rate used'!H23) -> 202.82084 | I23: =IF(OR('Revenue'!I23="",'FX rate used'!I23=""),"",'Revenue'!I23/'FX rate used'!I23) -> 206.3088 | J23: =IF(OR('Revenue'!J23="",'FX rate used'!J23=""),"",'Revenue'!J23/'FX rate used'!J23) -> 265.56503 | K23: =IF(OR('Revenue'!K23="",'FX rate used'!K23=""),"",'Revenue'!K23/'FX rate used'!K23) -> 313.51643 | L23: =IF(OR('Revenue'!L23="",'FX rate used'!L23=""),"",'Revenue'!L23/'FX rate used'!L23) -> 348.36819
A24: HMY | B24: Harmony Gold Mining Co Ltd | C24: USD | D24: 30 Jun | J24: =IF(OR('Revenue'!J24="",'FX rate used'!J24=""),"",'Revenue'!J24/'FX rate used'!J24) -> 2807.8914 | K24: =IF(OR('Revenue'!K24="",'FX rate used'!K24=""),"",'Revenue'!K24/'FX rate used'!K24) -> 2778.9242 | L24: =IF(OR('Revenue'!L24="",'FX rate used'!L24=""),"",'Revenue'!L24/'FX rate used'!L24) -> 3284.1377 | M24: =IF(OR('Revenue'!M24="",'FX rate used'!M24=""),"",'Revenue'!M24/'FX rate used'!M24) -> 4079.7357 | N24: =IF(OR('Revenue'!N24="",'FX rate used'!N24=""),"",'Revenue'!N24/'FX rate used'!N24) -> 5873.7737
A25: HUM.L | B25: Hummingbird Resources plc | C25: USD
A26: IAU.TO | B26: i-80 Gold Corp | C26: USD | D26: 31 Dec | J26: =IF(OR('Revenue'!J26="",'FX rate used'!J26=""),"",'Revenue'!J26/'FX rate used'!J26) -> 36.96 | K26: =IF(OR('Revenue'!K26="",'FX rate used'!K26=""),"",'Revenue'!K26/'FX rate used'!K26) -> 54.91 | L26: =IF(OR('Revenue'!L26="",'FX rate used'!L26=""),"",'Revenue'!L26/'FX rate used'!L26) -> 50.34 | M26: =IF(OR('Revenue'!M26="",'FX rate used'!M26=""),"",'Revenue'!M26/'FX rate used'!M26) -> 95.19
A27: IMG.TO | B27: IAMGOLD Corp | C27: USD | D27: 31 Dec | I27: =IF(OR('Revenue'!I27="",'FX rate used'!I27=""),"",'Revenue'!I27/'FX rate used'!I27) -> 875.5 | J27: =IF(OR('Revenue'!J27="",'FX rate used'!J27=""),"",'Revenue'!J27/'FX rate used'!J27) -> 958.8 | K27: =IF(OR('Revenue'!K27="",'FX rate used'!K27=""),"",'Revenue'!K27/'FX rate used'!K27) -> 987.1 | L27: =IF(OR('Revenue'!L27="",'FX rate used'!L27=""),"",'Revenue'!L27/'FX rate used'!L27) -> 1633 | M27: =IF(OR('Revenue'!M27="",'FX rate used'!M27=""),"",'Revenue'!M27/'FX rate used'!M27) -> 2852.8
A28: K.TO | B28: Kinross Gold Corp | C28: USD | D28: 31 Dec | I28: =IF(OR('Revenue'!I28="",'FX rate used'!I28=""),"",'Revenue'!I28/'FX rate used'!I28) -> 2599.6 | J28: =IF(OR('Revenue'!J28="",'FX rate used'!J28=""),"",'Revenue'!J28/'FX rate used'!J28) -> 3455.1 | K28: =IF(OR('Revenue'!K28="",'FX rate used'!K28=""),"",'Revenue'!K28/'FX rate used'!K28) -> 4239.7 | L28: =IF(OR('Revenue'!L28="",'FX rate used'!L28=""),"",'Revenue'!L28/'FX rate used'!L28) -> 5148.8 | M28: =IF(OR('Revenue'!M28="",'FX rate used'!M28=""),"",'Revenue'!M28/'FX rate used'!M28) -> 7051.1
A29: KNT.TO | B29: K92 Mining Inc | C29: USD | D29: 31 Dec | I29: =IF(OR('Revenue'!I29="",'FX rate used'!I29=""),"",'Revenue'!I29/'FX rate used'!I29) -> 154.33 | J29: =IF(OR('Revenue'!J29="",'FX rate used'!J29=""),"",'Revenue'!J29/'FX rate used'!J29) -> 188.19 | K29: =IF(OR('Revenue'!K29="",'FX rate used'!K29=""),"",'Revenue'!K29/'FX rate used'!K29) -> 200.25 | L29: =IF(OR('Revenue'!L29="",'FX rate used'!L29=""),"",'Revenue'!L29/'FX rate used'!L29) -> 350.62 | M29: =IF(OR('Revenue'!M29="",'FX rate used'!M29=""),"",'Revenue'!M29/'FX rate used'!M29) -> 595.25
A30: LYC.AX | B30: Lynas Rare Earths Ltd | C30: USD | D30: 30 Jun | J30: =IF(OR('Revenue'!J30="",'FX rate used'!J30=""),"",'Revenue'!J30/'FX rate used'!J30) -> 667.48166 | K30: =IF(OR('Revenue'!K30="",'FX rate used'!K30=""),"",'Revenue'!K30/'FX rate used'!K30) -> 497.42199 | L30: =IF(OR('Revenue'!L30="",'FX rate used'!L30=""),"",'Revenue'!L30/'FX rate used'!L30) -> 303.72622 | M30: =IF(OR('Revenue'!M30="",'FX rate used'!M30=""),"",'Revenue'!M30/'FX rate used'!M30) -> 360.35249 | N30: =IF(OR('Revenue'!N30="",'FX rate used'!N30=""),"",'Revenue'!N30/'FX rate used'!N30) -> 662.76173
A31: MSA.TO | B31: Mineros SA | C31: USD | D31: 31 Dec | I31: =IF(OR('Revenue'!I31="",'FX rate used'!I31=""),"",'Revenue'!I31/'FX rate used'!I31) -> 496.25 | J31: =IF(OR('Revenue'!J31="",'FX rate used'!J31=""),"",'Revenue'!J31/'FX rate used'!J31) -> 414.94 | K31: =IF(OR('Revenue'!K31="",'FX rate used'!K31=""),"",'Revenue'!K31/'FX rate used'!K31) -> 447.29 | L31: =IF(OR('Revenue'!L31="",'FX rate used'!L31=""),"",'Revenue'!L31/'FX rate used'!L31) -> 538.57 | M31: =IF(OR('Revenue'!M31="",'FX rate used'!M31=""),"",'Revenue'!M31/'FX rate used'!M31) -> 799.67
A32: MUX | B32: McEwen Mining Inc | C32: USD | D32: 31 Dec | I32: =IF(OR('Revenue'!I32="",'FX rate used'!I32=""),"",'Revenue'!I32/'FX rate used'!I32) -> 136.54 | J32: =IF(OR('Revenue'!J32="",'FX rate used'!J32=""),"",'Revenue'!J32/'FX rate used'!J32) -> 110.42 | K32: =IF(OR('Revenue'!K32="",'FX rate used'!K32=""),"",'Revenue'!K32/'FX rate used'!K32) -> 166.23 | L32: =IF(OR('Revenue'!L32="",'FX rate used'!L32=""),"",'Revenue'!L32/'FX rate used'!L32) -> 174.48 | M32: =IF(OR('Revenue'!M32="",'FX rate used'!M32=""),"",'Revenue'!M32/'FX rate used'!M32) -> 197.55
A33: NFGC.TO | B33: New Found Gold Corp | C33: USD | D33: 31 Dec | J33: =IF(OR('Revenue'!J33="",'FX rate used'!J33=""),"",'Revenue'!J33/'FX rate used'!J33) -> 0 | K33: =IF(OR('Revenue'!K33="",'FX rate used'!K33=""),"",'Revenue'!K33/'FX rate used'!K33) -> 0 | L33: =IF(OR('Revenue'!L33="",'FX rate used'!L33=""),"",'Revenue'!L33/'FX rate used'!L33) -> 0 | M33: =IF(OR('Revenue'!M33="",'FX rate used'!M33=""),"",'Revenue'!M33/'FX rate used'!M33) -> 4.1573912
A34: OBM.AX | B34: Ora Banda Mining Ltd | C34: USD | D34: 30 Jun | J34: =IF(OR('Revenue'!J34="",'FX rate used'!J34=""),"",'Revenue'!J34/'FX rate used'!J34) -> 111.91805 | K34: =IF(OR('Revenue'!K34="",'FX rate used'!K34=""),"",'Revenue'!K34/'FX rate used'!K34) -> 91.433116 | L34: =IF(OR('Revenue'!L34="",'FX rate used'!L34=""),"",'Revenue'!L34/'FX rate used'!L34) -> 140.45264 | M34: =IF(OR('Revenue'!M34="",'FX rate used'!M34=""),"",'Revenue'!M34/'FX rate used'!M34) -> 261.78668 | N34: =IF(OR('Revenue'!N34="",'FX rate used'!N34=""),"",'Revenue'!N34/'FX rate used'!N34) -> 547.24689
A35: OGC.TO | B35: OceanaGold Corp | C35: USD | D35: 31 Dec | I35: =IF(OR('Revenue'!I35="",'FX rate used'!I35=""),"",'Revenue'!I35/'FX rate used'!I35) -> 744.7 | J35: =IF(OR('Revenue'!J35="",'FX rate used'!J35=""),"",'Revenue'!J35/'FX rate used'!J35) -> 967.4 | K35: =IF(OR('Revenue'!K35="",'FX rate used'!K35=""),"",'Revenue'!K35/'FX rate used'!K35) -> 1026.3 | L35: =IF(OR('Revenue'!L35="",'FX rate used'!L35=""),"",'Revenue'!L35/'FX rate used'!L35) -> 1294 | M35: =IF(OR('Revenue'!M35="",'FX rate used'!M35=""),"",'Revenue'!M35/'FX rate used'!M35) -> 1893.2
A36: OGG.V | B36: Osisko Gold Group Inc (formerly Osisko Development) | C36: USD | D36: 31 Dec | I36: =IF(OR('Revenue'!I36="",'FX rate used'!I36=""),"",'Revenue'!I36/'FX rate used'!I36) -> 6.1110163 | J36: =IF(OR('Revenue'!J36="",'FX rate used'!J36=""),"",'Revenue'!J36/'FX rate used'!J36) -> 49.217666 | K36: =IF(OR('Revenue'!K36="",'FX rate used'!K36=""),"",'Revenue'!K36/'FX rate used'!K36) -> 23.431838 | L36: =IF(OR('Revenue'!L36="",'FX rate used'!L36=""),"",'Revenue'!L36/'FX rate used'!L36) -> 3.3296872 | M36: =IF(OR('Revenue'!M36="",'FX rate used'!M36=""),"",'Revenue'!M36/'FX rate used'!M36) -> 25.387993
A37: OLA.TO | B37: Orla Mining Ltd | C37: USD | D37: 31 Dec | I37: =IF(OR('Revenue'!I37="",'FX rate used'!I37=""),"",'Revenue'!I37/'FX rate used'!I37) -> 4.12 | J37: =IF(OR('Revenue'!J37="",'FX rate used'!J37=""),"",'Revenue'!J37/'FX rate used'!J37) -> 193.23 | K37: =IF(OR('Revenue'!K37="",'FX rate used'!K37=""),"",'Revenue'!K37/'FX rate used'!K37) -> 233.64 | L37: =IF(OR('Revenue'!L37="",'FX rate used'!L37=""),"",'Revenue'!L37/'FX rate used'!L37) -> 343.92 | M37: =IF(OR('Revenue'!M37="",'FX rate used'!M37=""),"",'Revenue'!M37/'FX rate used'!M37) -> 1057.88
A38: PGM.V | B38: Pure Gold Mining Inc | C38: USD
A39: PNR.AX | B39: Pantoro Gold Ltd | C39: USD | D39: 30 Jun | I39: =IF(OR('Revenue'!I39="",'FX rate used'!I39=""),"",'Revenue'!I39/'FX rate used'!I39) -> 65.497818 | J39: =IF(OR('Revenue'!J39="",'FX rate used'!J39=""),"",'Revenue'!J39/'FX rate used'!J39) -> 53.339911 | K39: =IF(OR('Revenue'!K39="",'FX rate used'!K39=""),"",'Revenue'!K39/'FX rate used'!K39) -> 66.302298 | L39: =IF(OR('Revenue'!L39="",'FX rate used'!L39=""),"",'Revenue'!L39/'FX rate used'!L39) -> 150.41099 | M39: =IF(OR('Revenue'!M39="",'FX rate used'!M39=""),"",'Revenue'!M39/'FX rate used'!M39) -> 231.35962
A40: PSAB.JK | B40: PT J Resources Asia Pasifik Tbk | C40: USD | D40: 31 Dec | I40: =IF(OR('Revenue'!I40="",'FX rate used'!I40=""),"",'Revenue'!I40/'FX rate used'!I40) -> 237.15 | J40: =IF(OR('Revenue'!J40="",'FX rate used'!J40=""),"",'Revenue'!J40/'FX rate used'!J40) -> 100.27 | K40: =IF(OR('Revenue'!K40="",'FX rate used'!K40=""),"",'Revenue'!K40/'FX rate used'!K40) -> 170.15 | L40: =IF(OR('Revenue'!L40="",'FX rate used'!L40=""),"",'Revenue'!L40/'FX rate used'!L40) -> 236.01 | M40: =IF(OR('Revenue'!M40="",'FX rate used'!M40=""),"",'Revenue'!M40/'FX rate used'!M40) -> 288.75
...

Sheet FX rate used
A1: ticker | B1: company | C1: currency | D1: fiscal year ends | E1: 2017 | F1: 2018 | G1: 2019 | H1: 2020 | I1: 2021 | J1: 2022 | K1: 2023 | L1: 2024 | M1: 2025 | N1: 2026
A2: 2259.HK | B2: Zijin Gold International Co Ltd | C2: USD | D2: 31 Dec | J2: 1 | K2: 1 | L2: 1 | M2: 1
A3: 600988.SS | B3: Chifeng Jilong Gold Mining Co Ltd | C3: CNY | D3: 31 Dec | I3: 6.450307 | J3: 6.729369 | K3: 7.071653 | L3: 7.186184 | M3: 7.186771
A4: AAUC.TO | B4: Allied Gold Corp | C4: USD | D4: 31 Dec | I4: 1 | J4: 1 | K4: 1 | L4: 1 | M4: 1
A5: AGI.TO | B5: Alamos Gold Inc | C5: USD | D5: 31 Dec | I5: 1 | J5: 1 | K5: 1 | L5: 1 | M5: 1
A6: ALK.AX | B6: Alkane Resources Ltd | C6: AUD | D6: 30 Jun | J6: 1.37833 | K6: 1.486223 | L6: 1.525354 | M6: 1.544349 | N6: 1.475568
A7: AMRQ.L | B7: Amaroq Minerals Ltd | C7: CAD | D7: 31 Dec | I7: 1.253474 | J7: 1.301362 | K7: 1.349446 | L7: 1.369498
A8: AR.TO | B8: Argonaut Gold Inc
A9: ASE.V | B9: Asante Gold Corp | C9: USD | D9: 31 Dec | I9: 1 | J9: 1 | K9: 1 | L9: 1 | M9: 1
A10: AU | B10: AngloGold Ashanti plc | C10: USD | D10: 31 Dec | I10: 1 | J10: 1 | K10: 1 | L10: 1 | M10: 1
A11: AUMB.V | B11: 1911 Gold Corp | C11: CAD | D11: 31 Dec | I11: 1.253474 | J11: 1.301362 | K11: 1.349446 | L11: 1.369498 | M11: 1.397511
A12: BGL.AX | B12: Bellevue Gold Ltd | C12: AUD | D12: 30 Jun | L12: 1.525354 | M12: 1.544349 | N12: 1.475568
A13: BTO.TO | B13: B2Gold Corp | C13: USD | D13: 31 Dec | I13: 1 | J13: 1 | K13: 1 | L13: 1 | M13: 1
A14: CERT.V | B14: Cerrado Gold Inc | C14: USD | D14: 31 Dec | I14: 1 | J14: 1 | K14: 1 | L14: 1 | M14: 1
A15: CG.TO | B15: Centerra Gold Inc | C15: USD | D15: 31 Dec | I15: 1 | J15: 1 | K15: 1 | L15: 1 | M15: 1
A16: CXB.TO | B16: Calibre Mining Corp | C16: USD | D16: 31 Dec | H16: 1 | I16: 1 | J16: 1 | K16: 1 | L16: 1
A17: CYL.AX | B17: Catalyst Metals Ltd | C17: AUD | D17: 30 Jun | J17: 1.37833 | K17: 1.486223 | L17: 1.525354 | M17: 1.544349 | N17: 1.475568
A18: ELD.TO | B18: Eldorado Gold Corp | C18: USD | D18: 31 Dec | I18: 1 | J18: 1 | K18: 1 | L18: 1 | M18: 1
A19: EQX.TO | B19: Equinox Gold Corp | C19: USD | D19: 31 Dec | I19: 1 | J19: 1 | K19: 1 | L19: 1 | M19: 1
A20: FVI.TO | B20: Fortuna Mining Corp | C20: USD | D20: 31 Dec | I20: 1 | J20: 1 | K20: 1 | L20: 1 | M20: 1
A21: GFI | B21: Gold Fields Ltd | C21: USD | D21: 31 Dec | I21: 1 | J21: 1 | K21: 1 | L21: 1 | M21: 1
A22: GMD.AX | B22: Genesis Minerals Ltd | C22: AUD | D22: 30 Jun | K22: 1.486223 | L22: 1.525354 | M22: 1.544349 | N22: 1.475568
A23: GOR.AX | B23: Gold Road Resources Ltd | C23: AUD | D23: 31 Dec | H23: 1.45276 | I23: 1.33179 | J23: 1.441982 | K23: 1.505886 | L23: 1.515523
A24: HMY | B24: Harmony Gold Mining Co Ltd | C24: ZAR | D24: 30 Jun | J24: 15.187553 | K24: 17.731682 | L24: 18.689533 | M24: 18.112938 | N24: 16.895101
A25: HUM.L | B25: Hummingbird Resources plc
A26: IAU.TO | B26: i-80 Gold Corp | C26: USD | D26: 31 Dec | J26: 1 | K26: 1 | L26: 1 | M26: 1
A27: IMG.TO | B27: IAMGOLD Corp | C27: USD | D27: 31 Dec | I27: 1 | J27: 1 | K27: 1 | L27: 1 | M27: 1
A28: K.TO | B28: Kinross Gold Corp | C28: USD | D28: 31 Dec | I28: 1 | J28: 1 | K28: 1 | L28: 1 | M28: 1
A29: KNT.TO | B29: K92 Mining Inc | C29: USD | D29: 31 Dec | I29: 1 | J29: 1 | K29: 1 | L29: 1 | M29: 1
A30: LYC.AX | B30: Lynas Rare Earths Ltd | C30: AUD | D30: 30 Jun | J30: 1.37833 | K30: 1.486223 | L30: 1.525354 | M30: 1.544349 | N30: 1.475568
A31: MSA.TO | B31: Mineros SA | C31: USD | D31: 31 Dec | I31: 1 | J31: 1 | K31: 1 | L31: 1 | M31: 1
A32: MUX | B32: McEwen Mining Inc | C32: USD | D32: 31 Dec | I32: 1 | J32: 1 | K32: 1 | L32: 1 | M32: 1
A33: NFGC.TO | B33: New Found Gold Corp | C33: CAD | D33: 31 Dec | J33: 1.301362 | K33: 1.349446 | L33: 1.369498 | M33: 1.397511
A34: OBM.AX | B34: Ora Banda Mining Ltd | C34: AUD | D34: 30 Jun | J34: 1.37833 | K34: 1.486223 | L34: 1.525354 | M34: 1.544349 | N34: 1.475568
A35: OGC.TO | B35: OceanaGold Corp | C35: USD | D35: 31 Dec | I35: 1 | J35: 1 | K35: 1 | L35: 1 | M35: 1
A36: OGG.V | B36: Osisko Gold Group Inc (formerly Osisko Development) | C36: CAD | D36: 31 Dec | I36: 1.253474 | J36: 1.301362 | K36: 1.349446 | L36: 1.369498 | M36: 1.397511
A37: OLA.TO | B37: Orla Mining Ltd | C37: USD | D37: 31 Dec | I37: 1 | J37: 1 | K37: 1 | L37: 1 | M37: 1
A38: PGM.V | B38: Pure Gold Mining Inc
A39: PNR.AX | B39: Pantoro Gold Ltd | C39: AUD | D39: 30 Jun | I39: 1.34035 | J39: 1.37833 | K39: 1.486223 | L39: 1.525354 | M39: 1.544349
A40: PSAB.JK | B40: PT J Resources Asia Pasifik Tbk | C40: USD | D40: 31 Dec | I40: 1 | J40: 1 | K40: 1 | L40: 1 | M40: 1
...

Sheet Verification
A1: StockAnalysis vs Yahoo Finance, same fiscal year (millions, reporting currency)
A2: 155 comparisons across 42 tickers: match: 146, DIFFERENT: 5, explained: 2, small difference (1-5%): 2
A3: DIFFERENT usually means one source restated the year (e.g. a sold mine moved to discontinued operations); the Revenue tab shows StockAnalysis and flags the cell.
A5: ticker | B5: fiscal_year | C5: period_end | D5: stockanalysis_m | E5: yahoo_m | F5: difference_% | G5: status
A6: BGL.AX | B6: 2025 | C6: 2025-06-30 | D6: 395 | E6: 505.8 | F6: -21.9 | G6: DIFFERENT
A7: CYL.AX | B7: 2024 | C7: 2024-06-30 | D7: 242 | E7: 317 | F7: -23.7 | G7: DIFFERENT
A8: LYC.AX | B8: 2023 | C8: 2023-06-30 | D8: 739.3 | E8: 787.1 | F8: -6.1 | G8: DIFFERENT
A9: SBM.AX | B9: 2022 | C9: 2022-06-30 | D9: 201.3 | E9: 680.3 | F9: -70.4 | G9: DIFFERENT
A10: SBM.AX | B10: 2024 | C10: 2024-06-30 | D10: 197.7 | E10: 223.6 | F10: -11.6 | G10: DIFFERENT
A11: AAUC.TO | B11: 2024 | C11: 2024-12-31 | D11: 730.4 | E11: 1331.8 | F11: -45.2 | G11: explained: Yahoo has 2024 and 2025 swapped; StockAnalysis matches Allied Gold's reported figures.
A12: AAUC.TO | B12: 2025 | C12: 2025-12-31 | D12: 1331.8 | E12: 730.4 | F12: 82.3 | G12: explained: Yahoo has 2024 and 2025 swapped; StockAnalysis matches Allied Gold's reported figures.
A13: 2259.HK | B13: 2022 | C13: 2022-12-31 | D13: 1818 | E13: 1818 | F13: 0 | G13: match
A14: 2259.HK | B14: 2023 | C14: 2023-12-31 | D14: 2262.4 | E14: 2262.4 | F14: 0 | G14: match
A15: 2259.HK | B15: 2024 | C15: 2024-12-31 | D15: 2989.9 | E15: 2989.9 | F15: 0 | G15: match
A16: 2259.HK | B16: 2025 | C16: 2025-12-31 | D16: 5383.5 | E16: 5383.5 | F16: 0 | G16: match
A17: 600988.SS | B17: 2022 | C17: 2022-12-31 | D17: 6266.8 | E17: 6266.8 | F17: 0 | G17: match
... A160: VAU.AX | B160: 2022 | C160: 2022-06-30 | D160: 165 | E160: 162.9 | F160: 1.3 | G160: small difference (1-5%)
