Workbook

Sheet Entities
A1: entity | B1: listed_parent | C1: ticker | D1: exchange | E1: currency | F1: note
A2: Agnico Eagle Mexico SA de CV | B2: Agnico Eagle Mines Ltd | C2: AEM | D2: NYSE | E2: USD | F2: Wholly owned subsidiary
A3: Agnico-Eagle Mines Limited | B3: Agnico Eagle Mines Ltd | C3: AEM | D3: NYSE | E3: USD
A4: Anglo Corporate Services South Africa | B4: Anglo American plc | C4: AAL.L | D4: LSE | E4: GBp | F4: Wholly owned subsidiary
A5: ArcelorMittal Mining UK Ltd | B5: ArcelorMittal SA | C5: MT | D5: NYSE | E5: USD | F5: Wholly owned subsidiary
A6: ASARCO, LLC | B6: Grupo Mexico SAB de CV | C6: GMEXICOB.MX | D6: BMV | E6: MXN | F6: Owned via Americas Mining Corp
A7: Barrick Gold of North America, Inc. | B7: Barrick Mining Corp | C7: B | D7: NYSE | E7: USD | F7: NYSE ticker was GOLD until May 2025
A8: BHP Billiton Iron Ore Pty Ltd | B8: BHP Group Ltd | C8: BHP.AX | D8: ASX | E8: AUD | F8: Wholly owned subsidiary
A9: BHP Canada Inc. | B9: BHP Group Ltd | C9: BHP.AX | D9: ASX | E9: AUD | F9: Wholly owned subsidiary
A10: Codelco Chile | F10: State-owned (Chile) - no listed shares
A11: Evolution Mining | B11: Evolution Mining Ltd | C11: EVN.AX | D11: ASX | E11: AUD
A12: FMG Procurement Services Pty Ltd | B12: Fortescue Ltd | C12: FMG.AX | D12: ASX | E12: AUD | F12: Wholly owned subsidiary
A13: Freeport McMoRan Inc. - Corporate Acc. | B13: Freeport-McMoRan Inc | C13: FCX | D13: NYSE | E13: USD
A14: Fresnillo Chile SPA | B14: Fresnillo plc | C14: FRES.L | D14: LSE | E14: GBp | F14: Wholly owned subsidiary
A15: Greenstone Gold Mines | B15: Equinox Gold Corp | C15: EQX | D15: NYSE American | E15: USD | F15: Equinox 100% since 2024 (earlier Premier Gold/Centerra/Orion JV)
A16: Industrial Minera Mexico S.A. de C.V. | B16: Southern Copper Corp | C16: SCCO | D16: NYSE | E16: USD | F16: Part of Minera Mexico (Southern Copper / Grupo Mexico)
A17: Lundin Mining Corporation | B17: Lundin Mining Corp | C17: LUN.TO | D17: TSX | E17: CAD
A18: Luossavaara-Kiirunavaara AB | F18: LKAB - state-owned (Sweden) - no listed shares
A19: Maaden - Exploration | B19: Saudi Arabian Mining Co (Maaden) | C19: 1211.SR | D19: Tadawul | E19: SAR
A20: MIM - a Glencore Company | B20: Glencore plc | C20: GLEN.L | D20: LSE | E20: GBp | F20: Mount Isa Mines - wholly owned
A21: Minera Escondida Ltda | B21: BHP Group Ltd | C21: BHP.AX | D21: ASX | E21: AUD | F21: BHP 57.5% / Rio Tinto 30% / JECO 12.5%
A22: Mineral Resources Limited | B22: Mineral Resources Ltd | C22: MIN.AX | D22: ASX | E22: AUD
A23: MMG | B23: MMG Ltd | C23: 1208.HK | D23: HKEX | E23: HKD
A24: Newmont Goldcorp Services Pty Ltd | B24: Newmont Corp | C24: NEM | D24: NYSE | E24: USD | F24: Wholly owned subsidiary
A25: NEXA RECURSOS MINERAIS S/A | B25: Nexa Resources SA | C25: NEXA | D25: NYSE | E25: USD | F25: Listed Oct 2017
A26: Northern Star Resources Limited | B26: Northern Star Resources Ltd | C26: NST.AX | D26: ASX | E26: AUD
A27: PT Vale Indonesia TBK | B27: PT Vale Indonesia Tbk | C27: INCO.JK | D27: IDX | E27: IDR
A28: PT Vale Indonesia TBK, OPG Tech Dept. | B28: PT Vale Indonesia Tbk | C28: INCO.JK | D28: IDX | E28: IDR
A29: Rio Tinto IS&T Asia Pacific | B29: Rio Tinto plc | C29: RIO.L | D29: LSE | E29: GBp | F29: Wholly owned subsidiary
A30: SGC - Servicio Geologico da Colombia | F30: Government agency (Colombia) - no shares
A31: VALE S.A. | B31: Vale SA | C31: VALE3.SA | D31: B3 | E31: BRL
A32: Vale S/A | B32: Vale SA | C32: VALE3.SA | D32: B3 | E32: BRL
A33: Zangge Mining Co., Ltd | B33: Zangge Mining Co Ltd | C33: 000408.SZ | D33: SZSE | E33: CNY
A34: Zijin Mining Corporation Co.,Ltd | B34: Zijin Mining Group Co Ltd | C34: 2899.HK | D34: HKEX | E34: HKD | F34: H-shares; A-shares are 601899.SS

Sheet Year-end close
A1: ticker | B1: company | C1: currency | D1: 2017 | E1: 2018 | F1: 2019 | G1: 2020 | H1: 2021 | I1: 2022 | J1: 2023 | K1: 2024 | L1: 2025 | M1: 2026
A2: 000408.SZ | B2: Zangge Mining Co Ltd | C2: CNY | D2: 17.7 | E2: 11.22 | F2: 7.38 | G2: 8.01 | H2: 41 | I2: 25.97 | J2: 25.34 | K2: 27.73 | L2: 84.4 | M2: 71.46
A3: 1208.HK | B3: MMG Ltd | C3: HKD | D3: 3.88 | E3: 3.37 | F3: 2.34 | G3: 3.35 | H3: 2.5 | I3: 2 | J3: 2.31 | K3: 2.57 | L3: 8.81 | M3: 8.545
A4: 1211.SR | B4: Saudi Arabian Mining Co (Maaden) | C4: SAR | D4: 52.1 | E4: 49.3 | F4: 44.4 | G4: 40.5 | H4: 78.5 | I4: 64.7 | J4: 48.55 | K4: 50.3 | L4: 60.95 | M4: 61.1
A5: 2899.HK | B5: Zijin Mining Group Co Ltd | C5: HKD | D5: 2.95 | E5: 2.97 | F5: 3.88 | G5: 8.77 | H5: 9.28 | I5: 10.58 | J5: 12.72 | K5: 14.16 | L5: 35.66 | M5: 32.5
A6: AAL.L | B6: Anglo American plc | C6: GBp | D6: 1549.5078 | E6: 1747.8088 | F6: 2173.0111 | G6: 2424.5124 | H6: 3015.987 | I6: 3236.4859 | J6: 1970.5915 | K6: 2363.9897 | L6: 3085 | M6: 4042
A7: AEM | B7: Agnico Eagle Mines Ltd | C7: USD | D7: 46.18 | E7: 40.4 | F7: 61.61 | G7: 70.51 | H7: 53.14 | I7: 51.99 | J7: 54.85 | K7: 78.21 | L7: 169.53 | M7: 194.48
A8: B | B8: Barrick Mining Corp | C8: USD | D8: 14.47 | E8: 13.54 | F8: 18.59 | G8: 22.78 | H8: 19 | I8: 17.18 | J8: 18.09 | K8: 15.5 | L8: 43.55 | M8: 42.88
A9: BHP.AX | B9: BHP Group Ltd | C9: AUD | D9: 29.5699 | E9: 34.2299 | F9: 38.9199 | G9: 42.4299 | H9: 41.4999 | I9: 45.63 | J9: 50.41 | K9: 39.55 | L9: 45.49 | M9: 60.72
A10: EQX | B10: Equinox Gold Corp | C10: USD | F10: 7.7 | G10: 10.34 | H10: 6.76 | I10: 3.28 | J10: 4.89 | K10: 5.02 | L10: 14.04 | M10: 11.94
A11: EVN.AX | B11: Evolution Mining Ltd | C11: AUD | D11: 2.65 | E11: 3.69 | F11: 3.8 | G11: 4.99 | H11: 4.06 | I11: 2.98 | J11: 3.96 | K11: 4.81 | L11: 12.68 | M11: 13.71
A12: FCX | B12: Freeport-McMoRan Inc | C12: USD | D12: 18.96 | E12: 10.31 | F12: 13.12 | G12: 26.02 | H12: 41.73 | I12: 38 | J12: 42.57 | K12: 38.08 | L12: 50.79 | M12: 72.31
A13: FMG.AX | B13: Fortescue Ltd | C13: AUD | D13: 4.88 | E13: 4.19 | F13: 10.69 | G13: 23.43 | H13: 19.21 | I13: 20.51 | J13: 29.02 | K13: 18.25 | L13: 22.01 | M13: 16.37
A14: FRES.L | B14: Fresnillo plc | C14: GBp | D14: 1429 | E14: 860 | F14: 640.2 | G14: 1129.5 | H14: 892.8 | I14: 901.8 | J14: 594.4 | K14: 621.5 | L14: 3334 | M14: 2890
A15: GLEN.L | B15: Glencore plc | C15: GBp | D15: 390 | E15: 291.35 | F15: 235.35 | G15: 233 | H15: 374.95 | I15: 552.4 | J15: 472.1 | K15: 353.4 | L15: 406.55 | M15: 561.1
A16: GMEXICOB.MX | B16: Grupo Mexico SAB de CV | C16: MXN | D16: 64.91 | E16: 40.44 | F16: 51.89 | G16: 84.12 | H16: 89.29 | I16: 68.7 | J16: 94.38 | K16: 99.28 | L16: 170.2001 | M16: 224.11
A17: INCO.JK | B17: PT Vale Indonesia Tbk | C17: IDR | D17: 2890 | E17: 3260 | F17: 3640 | G17: 5100 | H17: 4680 | I17: 7100 | J17: 4310 | K17: 3620 | L17: 5175 | M17: 4680
A18: LUN.TO | B18: Lundin Mining Corp | C18: CAD | D18: 8.36 | E18: 5.64 | F18: 7.76 | G18: 11.3 | H18: 9.88 | I18: 8.31 | J18: 10.84 | K18: 12.37 | L18: 29.5 | M18: 34.98
A19: MIN.AX | B19: Mineral Resources Ltd | C19: AUD | D19: 21.14 | E19: 15.47 | F19: 16.5 | G19: 37.45 | H19: 56 | I19: 77.2 | J19: 70 | K19: 34.25 | L19: 54.38 | M19: 52.41
A20: MT | B20: ArcelorMittal SA | C20: USD | D20: 32.31 | E20: 20.67 | F20: 17.54 | G20: 22.9 | H20: 31.83 | I20: 26.22 | J20: 28.39 | K20: 23.13 | L20: 45.57 | M20: 70.7
A21: NEM | B21: Newmont Corp | C21: USD | D21: 37.52 | E21: 34.65 | F21: 43.45 | G21: 59.89 | H21: 62.02 | I21: 47.2 | J21: 41.39 | K21: 37.22 | L21: 99.85 | M21: 121.43
A22: NEXA | B22: Nexa Resources SA | C22: USD | D22: 19.61 | E22: 11.9 | F22: 8.14 | G22: 9.64 | H22: 7.86 | I22: 6.03 | J22: 7.14 | K22: 8.8 | L22: 8.85 | M22: 12.44
... A26: VALE3.SA | B26: Vale SA | C26: BRL | D26: 40.26 | E26: 51 | F26: 53.3 | G26: 87.45 | H26: 77.96 | I26: 88.88 | J26: 77.2 | K26: 54.55 | L26: 71.96 | M26: 70.77
A28: Last close of each year, in the currency the stock trades in (GBp = pence). 2026 = latest close. Highlighted cells were corrected to the as-traded price; hover for Yahoo's rescaled figure.

Sheet Year-end close USD
A1: ticker | B1: company | C1: currency | D1: 2017 | E1: 2018 | F1: 2019 | G1: 2020 | H1: 2021 | I1: 2022 | J1: 2023 | K1: 2024 | L1: 2025 | M1: 2026
A2: 000408.SZ | B2: Zangge Mining Co Ltd | C2: USD | D2: =IF('Year-end close'!D2="","",'Year-end close'!D2/IF('Year-end close'!$C2="GBp",100,1)/INDEX('FX year-end'!$B$2:$B$11,MATCH(IF('Year-end close'!$C2="GBp","GBP",'Year-end close'!$C2),'FX year-end'!$A$2:$A$11,0))) -> 2.7099026 | E2: =IF('Year-end close'!E2="","",'Year-end close'!E2/IF('Year-end close'!$C2="GBp",100,1)/INDEX('FX year-end'!$C$2:$C$11,MATCH(IF('Year-end close'!$C2="GBp","GBP",'Year-end close'!$C2),'FX year-end'!$A$2:$A$11,0))) -> 1.6314779 | F2: =IF('Year-end close'!F2="","",'Year-end close'!F2/IF('Year-end close'!$C2="GBp",100,1)/INDEX('FX year-end'!$D$2:$D$11,MATCH(IF('Year-end close'!$C2="GBp","GBP",'Year-end close'!$C2),'FX year-end'!$A$2:$A$11,0))) -> 1.0564439 | G2: =IF('Year-end close'!G2="","",'Year-end close'!G2/IF('Year-end close'!$C2="GBp",100,1)/INDEX('FX year-end'!$E$2:$E$11,MATCH(IF('Year-end close'!$C2="GBp","GBP",'Year-end close'!$C2),'FX year-end'!$A$2:$A$11,0))) -> 1.2281132 | H2: =IF('Year-end close'!H2="","",'Year-end close'!H2/IF('Year-end close'!$C2="GBp",100,1)/INDEX('FX year-end'!$F$2:$F$11,MATCH(IF('Year-end close'!$C2="GBp","GBP",'Year-end close'!$C2),'FX year-end'!$A$2:$A$11,0))) -> 6.4342995 | I2: =IF('Year-end close'!I2="","",'Year-end close'!I2/IF('Year-end close'!$C2="GBp",100,1)/INDEX('FX year-end'!$G$2:$G$11,MATCH(IF('Year-end close'!$C2="GBp","GBP",'Year-end close'!$C2),'FX year-end'!$A$2:$A$11,0))) -> 3.7296606 | J2: =IF('Year-end close'!J2="","",'Year-end close'!J2/IF('Year-end close'!$C2="GBp",100,1)/INDEX('FX year-end'!$H$2:$H$11,MATCH(IF('Year-end close'!$C2="GBp","GBP",'Year-end close'!$C2),'FX year-end'!$A$2:$A$11,0))) -> 3.5654988 | K2: =IF('Year-end close'!K2="","",'Year-end close'!K2/IF('Year-end close'!$C2="GBp",100,1)/INDEX('FX year-end'!$I$2:$I$11,MATCH(IF('Year-end close'!$C2="GBp","GBP",'Year-end close'!$C2),'FX year-end'!$A$2:$A$11,0))) -> 3.7996191 | L2: =IF('Year-end close'!L2="","",'Year-end close'!L2/IF('Year-end close'!$C2="GBp",100,1)/INDEX('FX year-end'!$J$2:$J$11,MATCH(IF('Year-end close'!$C2="GBp","GBP",'Year-end close'!$C2),'FX year-end'!$A$2:$A$11,0))) -> 12.063864 | M2: =IF('Year-end close'!M2="","",'Year-end close'!M2/IF('Year-end close'!$C2="GBp",100,1)/INDEX('FX year-end'!$K$2:$K$11,MATCH(IF('Year-end close'!$C2="GBp","GBP",'Year-end close'!$C2),'FX year-end'!$A$2:$A$11,0))) -> 10.646127
A3: 1208.HK | B3: MMG Ltd | C3: USD | D3: =IF('Year-end close'!D3="","",'Year-end close'!D3/IF('Year-end close'!$C3="GBp",100,1)/INDEX('FX year-end'!$B$2:$B$11,MATCH(IF('Year-end close'!$C3="GBp","GBP",'Year-end close'!$C3),'FX year-end'!$A$2:$A$11,0))) -> 0.4963668 | E3: =IF('Year-end close'!E3="","",'Year-end close'!E3/IF('Year-end close'!$C3="GBp",100,1)/INDEX('FX year-end'!$C$2:$C$11,MATCH(IF('Year-end close'!$C3="GBp","GBP",'Year-end close'!$C3),'FX year-end'!$A$2:$A$11,0))) -> 0.43034645 | F3: =IF('Year-end close'!F3="","",'Year-end close'!F3/IF('Year-end close'!$C3="GBp",100,1)/INDEX('FX year-end'!$D$2:$D$11,MATCH(IF('Year-end close'!$C3="GBp","GBP",'Year-end close'!$C3),'FX year-end'!$A$2:$A$11,0))) -> 0.30045839 | G3: =IF('Year-end close'!G3="","",'Year-end close'!G3/IF('Year-end close'!$C3="GBp",100,1)/INDEX('FX year-end'!$E$2:$E$11,MATCH(IF('Year-end close'!$C3="GBp","GBP",'Year-end close'!$C3),'FX year-end'!$A$2:$A$11,0))) -> 0.43213651 | H3: =IF('Year-end close'!H3="","",'Year-end close'!H3/IF('Year-end close'!$C3="GBp",100,1)/INDEX('FX year-end'!$F$2:$F$11,MATCH(IF('Year-end close'!$C3="GBp","GBP",'Year-end close'!$C3),'FX year-end'!$A$2:$A$11,0))) -> 0.32061311 | I3: =IF('Year-end close'!I3="","",'Year-end close'!I3/IF('Year-end close'!$C3="GBp",100,1)/INDEX('FX year-end'!$G$2:$G$11,MATCH(IF('Year-end close'!$C3="GBp","GBP",'Year-end close'!$C3),'FX year-end'!$A$2:$A$11,0))) -> 0.25659448 | J3: =IF('Year-end close'!J3="","",'Year-end close'!J3/IF('Year-end close'!$C3="GBp",100,1)/INDEX('FX year-end'!$H$2:$H$11,MATCH(IF('Year-end close'!$C3="GBp","GBP",'Year-end close'!$C3),'FX year-end'!$A$2:$A$11,0))) -> 0.2957065 | K3: =IF('Year-end close'!K3="","",'Year-end close'!K3/IF('Year-end close'!$C3="GBp",100,1)/INDEX('FX year-end'!$I$2:$I$11,MATCH(IF('Year-end close'!$C3="GBp","GBP",'Year-end close'!$C3),'FX year-end'!$A$2:$A$11,0))) -> 0.33103626 | L3: =IF('Year-end close'!L3="","",'Year-end close'!L3/IF('Year-end close'!$C3="GBp",100,1)/INDEX('FX year-end'!$J$2:$J$11,MATCH(IF('Year-end close'!$C3="GBp","GBP",'Year-end close'!$C3),'FX year-end'!$A$2:$A$11,0))) -> 1.1322947 | M3: =IF('Year-end close'!M3="","",'Year-end close'!M3/IF('Year-end close'!$C3="GBp",100,1)/INDEX('FX year-end'!$K$2:$K$11,MATCH(IF('Year-end close'!$C3="GBp","GBP",'Year-end close'!$C3),'FX year-end'!$A$2:$A$11,0))) -> 1.089451
A4: 1211.SR | B4: Saudi Arabian Mining Co (Maaden) | C4: USD | D4: =IF('Year-end close'!D4="","",'Year-end close'!D4/IF('Year-end close'!$C4="GBp",100,1)/INDEX('FX year-end'!$B$2:$B$11,MATCH(IF('Year-end close'!$C4="GBp","GBP",'Year-end close'!$C4),'FX year-end'!$A$2:$A$11,0))) -> 13.909654 | E4: =IF('Year-end close'!E4="","",'Year-end close'!E4/IF('Year-end close'!$C4="GBp",100,1)/INDEX('FX year-end'!$C$2:$C$11,MATCH(IF('Year-end close'!$C4="GBp","GBP",'Year-end close'!$C4),'FX year-end'!$A$2:$A$11,0))) -> 13.14141 | F4: =IF('Year-end close'!F4="","",'Year-end close'!F4/IF('Year-end close'!$C4="GBp",100,1)/INDEX('FX year-end'!$D$2:$D$11,MATCH(IF('Year-end close'!$C4="GBp","GBP",'Year-end close'!$C4),'FX year-end'!$A$2:$A$11,0))) -> 11.84518 | G4: =IF('Year-end close'!G4="","",'Year-end close'!G4/IF('Year-end close'!$C4="GBp",100,1)/INDEX('FX year-end'!$E$2:$E$11,MATCH(IF('Year-end close'!$C4="GBp","GBP",'Year-end close'!$C4),'FX year-end'!$A$2:$A$11,0))) -> 10.806611 | H4: =IF('Year-end close'!H4="","",'Year-end close'!H4/IF('Year-end close'!$C4="GBp",100,1)/INDEX('FX year-end'!$F$2:$F$11,MATCH(IF('Year-end close'!$C4="GBp","GBP",'Year-end close'!$C4),'FX year-end'!$A$2:$A$11,0))) -> 20.93349 | I4: =IF('Year-end close'!I4="","",'Year-end close'!I4/IF('Year-end close'!$C4="GBp",100,1)/INDEX('FX year-end'!$G$2:$G$11,MATCH(IF('Year-end close'!$C4="GBp","GBP",'Year-end close'!$C4),'FX year-end'!$A$2:$A$11,0))) -> 17.230626 | J4: =IF('Year-end close'!J4="","",'Year-end close'!J4/IF('Year-end close'!$C4="GBp",100,1)/INDEX('FX year-end'!$H$2:$H$11,MATCH(IF('Year-end close'!$C4="GBp","GBP",'Year-end close'!$C4),'FX year-end'!$A$2:$A$11,0))) -> 12.963194 | K4: =IF('Year-end close'!K4="","",'Year-end close'!K4/IF('Year-end close'!$C4="GBp",100,1)/INDEX('FX year-end'!$I$2:$I$11,MATCH(IF('Year-end close'!$C4="GBp","GBP",'Year-end close'!$C4),'FX year-end'!$A$2:$A$11,0))) -> 13.406244 | L4: =IF('Year-end close'!L4="","",'Year-end close'!L4/IF('Year-end close'!$C4="GBp",100,1)/INDEX('FX year-end'!$J$2:$J$11,MATCH(IF('Year-end close'!$C4="GBp","GBP",'Year-end close'!$C4),'FX year-end'!$A$2:$A$11,0))) -> 16.26244 | M4: =IF('Year-end close'!M4="","",'Year-end close'!M4/IF('Year-end close'!$C4="GBp",100,1)/INDEX('FX year-end'!$K$2:$K$11,MATCH(IF('Year-end close'!$C4="GBp","GBP",'Year-end close'!$C4),'FX year-end'!$A$2:$A$11,0))) -> 16.274672
A5: 2899.HK | B5: Zijin Mining Group Co Ltd | C5: USD | D5: =IF('Year-end close'!D5="","",'Year-end close'!D5/IF('Year-end close'!$C5="GBp",100,1)/INDEX('FX year-end'!$B$2:$B$11,MATCH(IF('Year-end close'!$C5="GBp","GBP",'Year-end close'!$C5),'FX year-end'!$A$2:$A$11,0))) -> 0.37739228 | E5: =IF('Year-end close'!E5="","",'Year-end close'!E5/IF('Year-end close'!$C5="GBp",100,1)/INDEX('FX year-end'!$C$2:$C$11,MATCH(IF('Year-end close'!$C5="GBp","GBP",'Year-end close'!$C5),'FX year-end'!$A$2:$A$11,0))) -> 0.37926675 | F5: =IF('Year-end close'!F5="","",'Year-end close'!F5/IF('Year-end close'!$C5="GBp",100,1)/INDEX('FX year-end'!$D$2:$D$11,MATCH(IF('Year-end close'!$C5="GBp","GBP",'Year-end close'!$C5),'FX year-end'!$A$2:$A$11,0))) -> 0.49819597 | G5: =IF('Year-end close'!G5="","",'Year-end close'!G5/IF('Year-end close'!$C5="GBp",100,1)/INDEX('FX year-end'!$E$2:$E$11,MATCH(IF('Year-end close'!$C5="GBp","GBP",'Year-end close'!$C5),'FX year-end'!$A$2:$A$11,0))) -> 1.1312947 | H5: =IF('Year-end close'!H5="","",'Year-end close'!H5/IF('Year-end close'!$C5="GBp",100,1)/INDEX('FX year-end'!$F$2:$F$11,MATCH(IF('Year-end close'!$C5="GBp","GBP",'Year-end close'!$C5),'FX year-end'!$A$2:$A$11,0))) -> 1.1901159 | I5: =IF('Year-end close'!I5="","",'Year-end close'!I5/IF('Year-end close'!$C5="GBp",100,1)/INDEX('FX year-end'!$G$2:$G$11,MATCH(IF('Year-end close'!$C5="GBp","GBP",'Year-end close'!$C5),'FX year-end'!$A$2:$A$11,0))) -> 1.3573848 | J5: =IF('Year-end close'!J5="","",'Year-end close'!J5/IF('Year-end close'!$C5="GBp",100,1)/INDEX('FX year-end'!$H$2:$H$11,MATCH(IF('Year-end close'!$C5="GBp","GBP",'Year-end close'!$C5),'FX year-end'!$A$2:$A$11,0))) -> 1.6283059 | K5: =IF('Year-end close'!K5="","",'Year-end close'!K5/IF('Year-end close'!$C5="GBp",100,1)/INDEX('FX year-end'!$I$2:$I$11,MATCH(IF('Year-end close'!$C5="GBp","GBP",'Year-end close'!$C5),'FX year-end'!$A$2:$A$11,0))) -> 1.8239196 | L5: =IF('Year-end close'!L5="","",'Year-end close'!L5/IF('Year-end close'!$C5="GBp",100,1)/INDEX('FX year-end'!$J$2:$J$11,MATCH(IF('Year-end close'!$C5="GBp","GBP",'Year-end close'!$C5),'FX year-end'!$A$2:$A$11,0))) -> 4.5831588 | M5: =IF('Year-end close'!M5="","",'Year-end close'!M5/IF('Year-end close'!$C5="GBp",100,1)/INDEX('FX year-end'!$K$2:$K$11,MATCH(IF('Year-end close'!$C5="GBp","GBP",'Year-end close'!$C5),'FX year-end'!$A$2:$A$11,0))) -> 4.1436112
A6: AAL.L | B6: Anglo American plc | C6: USD | D6: =IF('Year-end close'!D6="","",'Year-end close'!D6/IF('Year-end close'!$C6="GBp",100,1)/INDEX('FX year-end'!$B$2:$B$11,MATCH(IF('Year-end close'!$C6="GBp","GBP",'Year-end close'!$C6),'FX year-end'!$A$2:$A$11,0))) -> 20.826718 | E6: =IF('Year-end close'!E6="","",'Year-end close'!E6/IF('Year-end close'!$C6="GBp",100,1)/INDEX('FX year-end'!$C$2:$C$11,MATCH(IF('Year-end close'!$C6="GBp","GBP",'Year-end close'!$C6),'FX year-end'!$A$2:$A$11,0))) -> 22.185946 | F6: =IF('Year-end close'!F6="","",'Year-end close'!F6/IF('Year-end close'!$C6="GBp",100,1)/INDEX('FX year-end'!$D$2:$D$11,MATCH(IF('Year-end close'!$C6="GBp","GBP",'Year-end close'!$C6),'FX year-end'!$A$2:$A$11,0))) -> 28.494769 | G6: =IF('Year-end close'!G6="","",'Year-end close'!G6/IF('Year-end close'!$C6="GBp",100,1)/INDEX('FX year-end'!$E$2:$E$11,MATCH(IF('Year-end close'!$C6="GBp","GBP",'Year-end close'!$C6),'FX year-end'!$A$2:$A$11,0))) -> 33.047713 | H6: =IF('Year-end close'!H6="","",'Year-end close'!H6/IF('Year-end close'!$C6="GBp",100,1)/INDEX('FX year-end'!$F$2:$F$11,MATCH(IF('Year-end close'!$C6="GBp","GBP",'Year-end close'!$C6),'FX year-end'!$A$2:$A$11,0))) -> 40.710919 | I6: =IF('Year-end close'!I6="","",'Year-end close'!I6/IF('Year-end close'!$C6="GBp",100,1)/INDEX('FX year-end'!$G$2:$G$11,MATCH(IF('Year-end close'!$C6="GBp","GBP",'Year-end close'!$C6),'FX year-end'!$A$2:$A$11,0))) -> 39.020133 | J6: =IF('Year-end close'!J6="","",'Year-end close'!J6/IF('Year-end close'!$C6="GBp",100,1)/INDEX('FX year-end'!$H$2:$H$11,MATCH(IF('Year-end close'!$C6="GBp","GBP",'Year-end close'!$C6),'FX year-end'!$A$2:$A$11,0))) -> 25.093487 | K6: =IF('Year-end close'!K6="","",'Year-end close'!K6/IF('Year-end close'!$C6="GBp",100,1)/INDEX('FX year-end'!$I$2:$I$11,MATCH(IF('Year-end close'!$C6="GBp","GBP",'Year-end close'!$C6),'FX year-end'!$A$2:$A$11,0))) -> 29.665939 | L6: =IF('Year-end close'!L6="","",'Year-end close'!L6/IF('Year-end close'!$C6="GBp",100,1)/INDEX('FX year-end'!$J$2:$J$11,MATCH(IF('Year-end close'!$C6="GBp","GBP",'Year-end close'!$C6),'FX year-end'!$A$2:$A$11,0))) -> 41.546304 | M6: =IF('Year-end close'!M6="","",'Year-end close'!M6/IF('Year-end close'!$C6="GBp",100,1)/INDEX('FX year-end'!$K$2:$K$11,MATCH(IF('Year-end close'!$C6="GBp","GBP",'Year-end close'!$C6),'FX year-end'!$A$2:$A$11,0))) -> 53.489665
A7: AEM | B7: Agnico Eagle Mines Ltd | C7: USD | D7: =IF('Year-end close'!D7="","",'Year-end close'!D7/IF('Year-end close'!$C7="GBp",100,1)/INDEX('FX year-end'!$B$2:$B$11,MATCH(IF('Year-end close'!$C7="GBp","GBP",'Year-end close'!$C7),'FX year-end'!$A$2:$A$11,0))) -> 46.18 | E7: =IF('Year-end close'!E7="","",'Year-end close'!E7/IF('Year-end close'!$C7="GBp",100,1)/INDEX('FX year-end'!$C$2:$C$11,MATCH(IF('Year-end close'!$C7="GBp","GBP",'Year-end close'!$C7),'FX year-end'!$A$2:$A$11,0))) -> 40.4 | F7: =IF('Year-end close'!F7="","",'Year-end close'!F7/IF('Year-end close'!$C7="GBp",100,1)/INDEX('FX year-end'!$D$2:$D$11,MATCH(IF('Year-end close'!$C7="GBp","GBP",'Year-end close'!$C7),'FX year-end'!$A$2:$A$11,0))) -> 61.61 | G7: =IF('Year-end close'!G7="","",'Year-end close'!G7/IF('Year-end close'!$C7="GBp",100,1)/INDEX('FX year-end'!$E$2:$E$11,MATCH(IF('Year-end close'!$C7="GBp","GBP",'Year-end close'!$C7),'FX year-end'!$A$2:$A$11,0))) -> 70.51 | H7: =IF('Year-end close'!H7="","",'Year-end close'!H7/IF('Year-end close'!$C7="GBp",100,1)/INDEX('FX year-end'!$F$2:$F$11,MATCH(IF('Year-end close'!$C7="GBp","GBP",'Year-end close'!$C7),'FX year-end'!$A$2:$A$11,0))) -> 53.14 | I7: =IF('Year-end close'!I7="","",'Year-end close'!I7/IF('Year-end close'!$C7="GBp",100,1)/INDEX('FX year-end'!$G$2:$G$11,MATCH(IF('Year-end close'!$C7="GBp","GBP",'Year-end close'!$C7),'FX year-end'!$A$2:$A$11,0))) -> 51.99 | J7: =IF('Year-end close'!J7="","",'Year-end close'!J7/IF('Year-end close'!$C7="GBp",100,1)/INDEX('FX year-end'!$H$2:$H$11,MATCH(IF('Year-end close'!$C7="GBp","GBP",'Year-end close'!$C7),'FX year-end'!$A$2:$A$11,0))) -> 54.85 | K7: =IF('Year-end close'!K7="","",'Year-end close'!K7/IF('Year-end close'!$C7="GBp",100,1)/INDEX('FX year-end'!$I$2:$I$11,MATCH(IF('Year-end close'!$C7="GBp","GBP",'Year-end close'!$C7),'FX year-end'!$A$2:$A$11,0))) -> 78.21 | L7: =IF('Year-end close'!L7="","",'Year-end close'!L7/IF('Year-end close'!$C7="GBp",100,1)/INDEX('FX year-end'!$J$2:$J$11,MATCH(IF('Year-end close'!$C7="GBp","GBP",'Year-end close'!$C7),'FX year-end'!$A$2:$A$11,0))) -> 169.53 | M7: =IF('Year-end close'!M7="","",'Year-end close'!M7/IF('Year-end close'!$C7="GBp",100,1)/INDEX('FX year-end'!$K$2:$K$11,MATCH(IF('Year-end close'!$C7="GBp","GBP",'Year-end close'!$C7),'FX year-end'!$A$2:$A$11,0))) -> 194.48
A8: B | B8: Barrick Mining Corp | C8: USD | D8: =IF('Year-end close'!D8="","",'Year-end close'!D8/IF('Year-end close'!$C8="GBp",100,1)/INDEX('FX year-end'!$B$2:$B$11,MATCH(IF('Year-end close'!$C8="GBp","GBP",'Year-end close'!$C8),'FX year-end'!$A$2:$A$11,0))) -> 14.47 | E8: =IF('Year-end close'!E8="","",'Year-end close'!E8/IF('Year-end close'!$C8="GBp",100,1)/INDEX('FX year-end'!$C$2:$C$11,MATCH(IF('Year-end close'!$C8="GBp","GBP",'Year-end close'!$C8),'FX year-end'!$A$2:$A$11,0))) -> 13.54 | F8: =IF('Year-end close'!F8="","",'Year-end close'!F8/IF('Year-end close'!$C8="GBp",100,1)/INDEX('FX year-end'!$D$2:$D$11,MATCH(IF('Year-end close'!$C8="GBp","GBP",'Year-end close'!$C8),'FX year-end'!$A$2:$A$11,0))) -> 18.59 | G8: =IF('Year-end close'!G8="","",'Year-end close'!G8/IF('Year-end close'!$C8="GBp",100,1)/INDEX('FX year-end'!$E$2:$E$11,MATCH(IF('Year-end close'!$C8="GBp","GBP",'Year-end close'!$C8),'FX year-end'!$A$2:$A$11,0))) -> 22.78 | H8: =IF('Year-end close'!H8="","",'Year-end close'!H8/IF('Year-end close'!$C8="GBp",100,1)/INDEX('FX year-end'!$F$2:$F$11,MATCH(IF('Year-end close'!$C8="GBp","GBP",'Year-end close'!$C8),'FX year-end'!$A$2:$A$11,0))) -> 19 | I8: =IF('Year-end close'!I8="","",'Year-end close'!I8/IF('Year-end close'!$C8="GBp",100,1)/INDEX('FX year-end'!$G$2:$G$11,MATCH(IF('Year-end close'!$C8="GBp","GBP",'Year-end close'!$C8),'FX year-end'!$A$2:$A$11,0))) -> 17.18 | J8: =IF('Year-end close'!J8="","",'Year-end close'!J8/IF('Year-end close'!$C8="GBp",100,1)/INDEX('FX year-end'!$H$2:$H$11,MATCH(IF('Year-end close'!$C8="GBp","GBP",'Year-end close'!$C8),'FX year-end'!$A$2:$A$11,0))) -> 18.09 | K8: =IF('Year-end close'!K8="","",'Year-end close'!K8/IF('Year-end close'!$C8="GBp",100,1)/INDEX('FX year-end'!$I$2:$I$11,MATCH(IF('Year-end close'!$C8="GBp","GBP",'Year-end close'!$C8),'FX year-end'!$A$2:$A$11,0))) -> 15.5 | L8: =IF('Year-end close'!L8="","",'Year-end close'!L8/IF('Year-end close'!$C8="GBp",100,1)/INDEX('FX year-end'!$J$2:$J$11,MATCH(IF('Year-end close'!$C8="GBp","GBP",'Year-end close'!$C8),'FX year-end'!$A$2:$A$11,0))) -> 43.55 | M8: =IF('Year-end close'!M8="","",'Year-end close'!M8/IF('Year-end close'!$C8="GBp",100,1)/INDEX('FX year-end'!$K$2:$K$11,MATCH(IF('Year-end close'!$C8="GBp","GBP",'Year-end close'!$C8),'FX year-end'!$A$2:$A$11,0))) -> 42.88
A9: BHP.AX | B9: BHP Group Ltd | C9: USD | D9: =IF('Year-end close'!D9="","",'Year-end close'!D9/IF('Year-end close'!$C9="GBp",100,1)/INDEX('FX year-end'!$B$2:$B$11,MATCH(IF('Year-end close'!$C9="GBp","GBP",'Year-end close'!$C9),'FX year-end'!$A$2:$A$11,0))) -> 23.047647 | E9: =IF('Year-end close'!E9="","",'Year-end close'!E9/IF('Year-end close'!$C9="GBp",100,1)/INDEX('FX year-end'!$C$2:$C$11,MATCH(IF('Year-end close'!$C9="GBp","GBP",'Year-end close'!$C9),'FX year-end'!$A$2:$A$11,0))) -> 24.114054 | F9: =IF('Year-end close'!F9="","",'Year-end close'!F9/IF('Year-end close'!$C9="GBp",100,1)/INDEX('FX year-end'!$D$2:$D$11,MATCH(IF('Year-end close'!$C9="GBp","GBP",'Year-end close'!$C9),'FX year-end'!$A$2:$A$11,0))) -> 27.249374 | G9: =IF('Year-end close'!G9="","",'Year-end close'!G9/IF('Year-end close'!$C9="GBp",100,1)/INDEX('FX year-end'!$E$2:$E$11,MATCH(IF('Year-end close'!$C9="GBp","GBP",'Year-end close'!$C9),'FX year-end'!$A$2:$A$11,0))) -> 32.625585 | H9: =IF('Year-end close'!H9="","",'Year-end close'!H9/IF('Year-end close'!$C9="GBp",100,1)/INDEX('FX year-end'!$F$2:$F$11,MATCH(IF('Year-end close'!$C9="GBp","GBP",'Year-end close'!$C9),'FX year-end'!$A$2:$A$11,0))) -> 30.086606 | I9: =IF('Year-end close'!I9="","",'Year-end close'!I9/IF('Year-end close'!$C9="GBp",100,1)/INDEX('FX year-end'!$G$2:$G$11,MATCH(IF('Year-end close'!$C9="GBp","GBP",'Year-end close'!$C9),'FX year-end'!$A$2:$A$11,0))) -> 30.873261 | J9: =IF('Year-end close'!J9="","",'Year-end close'!J9/IF('Year-end close'!$C9="GBp",100,1)/INDEX('FX year-end'!$H$2:$H$11,MATCH(IF('Year-end close'!$C9="GBp","GBP",'Year-end close'!$C9),'FX year-end'!$A$2:$A$11,0))) -> 34.411388 | K9: =IF('Year-end close'!K9="","",'Year-end close'!K9/IF('Year-end close'!$C9="GBp",100,1)/INDEX('FX year-end'!$I$2:$I$11,MATCH(IF('Year-end close'!$C9="GBp","GBP",'Year-end close'!$C9),'FX year-end'!$A$2:$A$11,0))) -> 24.600101 | L9: =IF('Year-end close'!L9="","",'Year-end close'!L9/IF('Year-end close'!$C9="GBp",100,1)/INDEX('FX year-end'!$J$2:$J$11,MATCH(IF('Year-end close'!$C9="GBp","GBP",'Year-end close'!$C9),'FX year-end'!$A$2:$A$11,0))) -> 30.469202 | M9: =IF('Year-end close'!M9="","",'Year-end close'!M9/IF('Year-end close'!$C9="GBp",100,1)/INDEX('FX year-end'!$K$2:$K$11,MATCH(IF('Year-end close'!$C9="GBp","GBP",'Year-end close'!$C9),'FX year-end'!$A$2:$A$11,0))) -> 42.586618
A10: EQX | B10: Equinox Gold Corp | C10: USD | D10: =IF('Year-end close'!D10="","",'Year-end close'!D10/IF('Year-end close'!$C10="GBp",100,1)/INDEX('FX year-end'!$B$2:$B$11,MATCH(IF('Year-end close'!$C10="GBp","GBP",'Year-end close'!$C10),'FX year-end'!$A$2:$A$11,0))) | E10: =IF('Year-end close'!E10="","",'Year-end close'!E10/IF('Year-end close'!$C10="GBp",100,1)/INDEX('FX year-end'!$C$2:$C$11,MATCH(IF('Year-end close'!$C10="GBp","GBP",'Year-end close'!$C10),'FX year-end'!$A$2:$A$11,0))) | F10: =IF('Year-end close'!F10="","",'Year-end close'!F10/IF('Year-end close'!$C10="GBp",100,1)/INDEX('FX year-end'!$D$2:$D$11,MATCH(IF('Year-end close'!$C10="GBp","GBP",'Year-end close'!$C10),'FX year-end'!$A$2:$A$11,0))) -> 7.7 | G10: =IF('Year-end close'!G10="","",'Year-end close'!G10/IF('Year-end close'!$C10="GBp",100,1)/INDEX('FX year-end'!$E$2:$E$11,MATCH(IF('Year-end close'!$C10="GBp","GBP",'Year-end close'!$C10),'FX year-end'!$A$2:$A$11,0))) -> 10.34 | H10: =IF('Year-end close'!H10="","",'Year-end close'!H10/IF('Year-end close'!$C10="GBp",100,1)/INDEX('FX year-end'!$F$2:$F$11,MATCH(IF('Year-end close'!$C10="GBp","GBP",'Year-end close'!$C10),'FX year-end'!$A$2:$A$11,0))) -> 6.76 | I10: =IF('Year-end close'!I10="","",'Year-end close'!I10/IF('Year-end close'!$C10="GBp",100,1)/INDEX('FX year-end'!$G$2:$G$11,MATCH(IF('Year-end close'!$C10="GBp","GBP",'Year-end close'!$C10),'FX year-end'!$A$2:$A$11,0))) -> 3.28 | J10: =IF('Year-end close'!J10="","",'Year-end close'!J10/IF('Year-end close'!$C10="GBp",100,1)/INDEX('FX year-end'!$H$2:$H$11,MATCH(IF('Year-end close'!$C10="GBp","GBP",'Year-end close'!$C10),'FX year-end'!$A$2:$A$11,0))) -> 4.89 | K10: =IF('Year-end close'!K10="","",'Year-end close'!K10/IF('Year-end close'!$C10="GBp",100,1)/INDEX('FX year-end'!$I$2:$I$11,MATCH(IF('Year-end close'!$C10="GBp","GBP",'Year-end close'!$C10),'FX year-end'!$A$2:$A$11,0))) -> 5.02 | L10: =IF('Year-end close'!L10="","",'Year-end close'!L10/IF('Year-end close'!$C10="GBp",100,1)/INDEX('FX year-end'!$J$2:$J$11,MATCH(IF('Year-end close'!$C10="GBp","GBP",'Year-end close'!$C10),'FX year-end'!$A$2:$A$11,0))) -> 14.04 | M10: =IF('Year-end close'!M10="","",'Year-end close'!M10/IF('Year-end close'!$C10="GBp",100,1)/INDEX('FX year-end'!$K$2:$K$11,MATCH(IF('Year-end close'!$C10="GBp","GBP",'Year-end close'!$C10),'FX year-end'!$A$2:$A$11,0))) -> 11.94
A11: EVN.AX | B11: Evolution Mining Ltd | C11: USD | D11: =IF('Year-end close'!D11="","",'Year-end close'!D11/IF('Year-end close'!$C11="GBp",100,1)/INDEX('FX year-end'!$B$2:$B$11,MATCH(IF('Year-end close'!$C11="GBp","GBP",'Year-end close'!$C11),'FX year-end'!$A$2:$A$11,0))) -> 2.0654876 | E11: =IF('Year-end close'!E11="","",'Year-end close'!E11/IF('Year-end close'!$C11="GBp",100,1)/INDEX('FX year-end'!$C$2:$C$11,MATCH(IF('Year-end close'!$C11="GBp","GBP",'Year-end close'!$C11),'FX year-end'!$A$2:$A$11,0))) -> 2.5995069 | F11: =IF('Year-end close'!F11="","",'Year-end close'!F11/IF('Year-end close'!$C11="GBp",100,1)/INDEX('FX year-end'!$D$2:$D$11,MATCH(IF('Year-end close'!$C11="GBp","GBP",'Year-end close'!$C11),'FX year-end'!$A$2:$A$11,0))) -> 2.6605316 | G11: =IF('Year-end close'!G11="","",'Year-end close'!G11/IF('Year-end close'!$C11="GBp",100,1)/INDEX('FX year-end'!$E$2:$E$11,MATCH(IF('Year-end close'!$C11="GBp","GBP",'Year-end close'!$C11),'FX year-end'!$A$2:$A$11,0))) -> 3.8369563 | H11: =IF('Year-end close'!H11="","",'Year-end close'!H11/IF('Year-end close'!$C11="GBp",100,1)/INDEX('FX year-end'!$F$2:$F$11,MATCH(IF('Year-end close'!$C11="GBp","GBP",'Year-end close'!$C11),'FX year-end'!$A$2:$A$11,0))) -> 2.9434196 | I11: =IF('Year-end close'!I11="","",'Year-end close'!I11/IF('Year-end close'!$C11="GBp",100,1)/INDEX('FX year-end'!$G$2:$G$11,MATCH(IF('Year-end close'!$C11="GBp","GBP",'Year-end close'!$C11),'FX year-end'!$A$2:$A$11,0))) -> 2.0162682 | J11: =IF('Year-end close'!J11="","",'Year-end close'!J11/IF('Year-end close'!$C11="GBp",100,1)/INDEX('FX year-end'!$H$2:$H$11,MATCH(IF('Year-end close'!$C11="GBp","GBP",'Year-end close'!$C11),'FX year-end'!$A$2:$A$11,0))) -> 2.7032156 | K11: =IF('Year-end close'!K11="","",'Year-end close'!K11/IF('Year-end close'!$C11="GBp",100,1)/INDEX('FX year-end'!$I$2:$I$11,MATCH(IF('Year-end close'!$C11="GBp","GBP",'Year-end close'!$C11),'FX year-end'!$A$2:$A$11,0))) -> 2.9918201 | L11: =IF('Year-end close'!L11="","",'Year-end close'!L11/IF('Year-end close'!$C11="GBp",100,1)/INDEX('FX year-end'!$J$2:$J$11,MATCH(IF('Year-end close'!$C11="GBp","GBP",'Year-end close'!$C11),'FX year-end'!$A$2:$A$11,0))) -> 8.4930639 | M11: =IF('Year-end close'!M11="","",'Year-end close'!M11/IF('Year-end close'!$C11="GBp",100,1)/INDEX('FX year-end'!$K$2:$K$11,MATCH(IF('Year-end close'!$C11="GBp","GBP",'Year-end close'!$C11),'FX year-end'!$A$2:$A$11,0))) -> 9.6156544
A12: FCX | B12: Freeport-McMoRan Inc | C12: USD | D12: =IF('Year-end close'!D12="","",'Year-end close'!D12/IF('Year-end close'!$C12="GBp",100,1)/INDEX('FX year-end'!$B$2:$B$11,MATCH(IF('Year-end close'!$C12="GBp","GBP",'Year-end close'!$C12),'FX year-end'!$A$2:$A$11,0))) -> 18.96 | E12: =IF('Year-end close'!E12="","",'Year-end close'!E12/IF('Year-end close'!$C12="GBp",100,1)/INDEX('FX year-end'!$C$2:$C$11,MATCH(IF('Year-end close'!$C12="GBp","GBP",'Year-end close'!$C12),'FX year-end'!$A$2:$A$11,0))) -> 10.31 | F12: =IF('Year-end close'!F12="","",'Year-end close'!F12/IF('Year-end close'!$C12="GBp",100,1)/INDEX('FX year-end'!$D$2:$D$11,MATCH(IF('Year-end close'!$C12="GBp","GBP",'Year-end close'!$C12),'FX year-end'!$A$2:$A$11,0))) -> 13.12 | G12: =IF('Year-end close'!G12="","",'Year-end close'!G12/IF('Year-end close'!$C12="GBp",100,1)/INDEX('FX year-end'!$E$2:$E$11,MATCH(IF('Year-end close'!$C12="GBp","GBP",'Year-end close'!$C12),'FX year-end'!$A$2:$A$11,0))) -> 26.02 | H12: =IF('Year-end close'!H12="","",'Year-end close'!H12/IF('Year-end close'!$C12="GBp",100,1)/INDEX('FX year-end'!$F$2:$F$11,MATCH(IF('Year-end close'!$C12="GBp","GBP",'Year-end close'!$C12),'FX year-end'!$A$2:$A$11,0))) -> 41.73 | I12: =IF('Year-end close'!I12="","",'Year-end close'!I12/IF('Year-end close'!$C12="GBp",100,1)/INDEX('FX year-end'!$G$2:$G$11,MATCH(IF('Year-end close'!$C12="GBp","GBP",'Year-end close'!$C12),'FX year-end'!$A$2:$A$11,0))) -> 38 | J12: =IF('Year-end close'!J12="","",'Year-end close'!J12/IF('Year-end close'!$C12="GBp",100,1)/INDEX('FX year-end'!$H$2:$H$11,MATCH(IF('Year-end close'!$C12="GBp","GBP",'Year-end close'!$C12),'FX year-end'!$A$2:$A$11,0))) -> 42.57 | K12: =IF('Year-end close'!K12="","",'Year-end close'!K12/IF('Year-end close'!$C12="GBp",100,1)/INDEX('FX year-end'!$I$2:$I$11,MATCH(IF('Year-end close'!$C12="GBp","GBP",'Year-end close'!$C12),'FX year-end'!$A$2:$A$11,0))) -> 38.08 | L12: =IF('Year-end close'!L12="","",'Year-end close'!L12/IF('Year-end close'!$C12="GBp",100,1)/INDEX('FX year-end'!$J$2:$J$11,MATCH(IF('Year-end close'!$C12="GBp","GBP",'Year-end close'!$C12),'FX year-end'!$A$2:$A$11,0))) -> 50.79 | M12: =IF('Year-end close'!M12="","",'Year-end close'!M12/IF('Year-end close'!$C12="GBp",100,1)/INDEX('FX year-end'!$K$2:$K$11,MATCH(IF('Year-end close'!$C12="GBp","GBP",'Year-end close'!$C12),'FX year-end'!$A$2:$A$11,0))) -> 72.31
A13: FMG.AX | B13: Fortescue Ltd | C13: USD | D13: =IF('Year-end close'!D13="","",'Year-end close'!D13/IF('Year-end close'!$C13="GBp",100,1)/INDEX('FX year-end'!$B$2:$B$11,MATCH(IF('Year-end close'!$C13="GBp","GBP",'Year-end close'!$C13),'FX year-end'!$A$2:$A$11,0))) -> 3.803615 | E13: =IF('Year-end close'!E13="","",'Year-end close'!E13/IF('Year-end close'!$C13="GBp",100,1)/INDEX('FX year-end'!$C$2:$C$11,MATCH(IF('Year-end close'!$C13="GBp","GBP",'Year-end close'!$C13),'FX year-end'!$A$2:$A$11,0))) -> 2.9517436 | F13: =IF('Year-end close'!F13="","",'Year-end close'!F13/IF('Year-end close'!$C13="GBp",100,1)/INDEX('FX year-end'!$D$2:$D$11,MATCH(IF('Year-end close'!$C13="GBp","GBP",'Year-end close'!$C13),'FX year-end'!$A$2:$A$11,0))) -> 7.4844954 | G13: =IF('Year-end close'!G13="","",'Year-end close'!G13/IF('Year-end close'!$C13="GBp",100,1)/INDEX('FX year-end'!$E$2:$E$11,MATCH(IF('Year-end close'!$C13="GBp","GBP",'Year-end close'!$C13),'FX year-end'!$A$2:$A$11,0))) -> 18.016009 | H13: =IF('Year-end close'!H13="","",'Year-end close'!H13/IF('Year-end close'!$C13="GBp",100,1)/INDEX('FX year-end'!$F$2:$F$11,MATCH(IF('Year-end close'!$C13="GBp","GBP",'Year-end close'!$C13),'FX year-end'!$A$2:$A$11,0))) -> 13.92687 | I13: =IF('Year-end close'!I13="","",'Year-end close'!I13/IF('Year-end close'!$C13="GBp",100,1)/INDEX('FX year-end'!$G$2:$G$11,MATCH(IF('Year-end close'!$C13="GBp","GBP",'Year-end close'!$C13),'FX year-end'!$A$2:$A$11,0))) -> 13.877067 | J13: =IF('Year-end close'!J13="","",'Year-end close'!J13/IF('Year-end close'!$C13="GBp",100,1)/INDEX('FX year-end'!$H$2:$H$11,MATCH(IF('Year-end close'!$C13="GBp","GBP",'Year-end close'!$C13),'FX year-end'!$A$2:$A$11,0))) -> 19.809928 | K13: =IF('Year-end close'!K13="","",'Year-end close'!K13/IF('Year-end close'!$C13="GBp",100,1)/INDEX('FX year-end'!$I$2:$I$11,MATCH(IF('Year-end close'!$C13="GBp","GBP",'Year-end close'!$C13),'FX year-end'!$A$2:$A$11,0))) -> 11.3515 | L13: =IF('Year-end close'!L13="","",'Year-end close'!L13/IF('Year-end close'!$C13="GBp",100,1)/INDEX('FX year-end'!$J$2:$J$11,MATCH(IF('Year-end close'!$C13="GBp","GBP",'Year-end close'!$C13),'FX year-end'!$A$2:$A$11,0))) -> 14.742298 | M13: =IF('Year-end close'!M13="","",'Year-end close'!M13/IF('Year-end close'!$C13="GBp",100,1)/INDEX('FX year-end'!$K$2:$K$11,MATCH(IF('Year-end close'!$C13="GBp","GBP",'Year-end close'!$C13),'FX year-end'!$A$2:$A$11,0))) -> 11.481274
... A26: VALE3.SA | B26: Vale SA | C26: USD | D26: =IF('Year-end close'!D26="","",'Year-end close'!D26/IF('Year-end close'!$C26="GBp",100,1)/INDEX('FX year-end'!$B$2:$B$11,MATCH(IF('Year-end close'!$C26="GBp","GBP",'Year-end close'!$C26),'FX year-end'!$A$2:$A$11,0))) -> 12.159101 | E26: =IF('Year-end close'!E26="","",'Year-end close'!E26/IF('Year-end close'!$C26="GBp",100,1)/INDEX('FX year-end'!$C$2:$C$11,MATCH(IF('Year-end close'!$C26="GBp","GBP",'Year-end close'!$C26),'FX year-end'!$A$2:$A$11,0))) -> 13.164008 | F26: =IF('Year-end close'!F26="","",'Year-end close'!F26/IF('Year-end close'!$C26="GBp",100,1)/INDEX('FX year-end'!$D$2:$D$11,MATCH(IF('Year-end close'!$C26="GBp","GBP",'Year-end close'!$C26),'FX year-end'!$A$2:$A$11,0))) -> 13.272867 | G26: =IF('Year-end close'!G26="","",'Year-end close'!G26/IF('Year-end close'!$C26="GBp",100,1)/INDEX('FX year-end'!$E$2:$E$11,MATCH(IF('Year-end close'!$C26="GBp","GBP",'Year-end close'!$C26),'FX year-end'!$A$2:$A$11,0))) -> 16.846988 | H26: =IF('Year-end close'!H26="","",'Year-end close'!H26/IF('Year-end close'!$C26="GBp",100,1)/INDEX('FX year-end'!$F$2:$F$11,MATCH(IF('Year-end close'!$C26="GBp","GBP",'Year-end close'!$C26),'FX year-end'!$A$2:$A$11,0))) -> 13.995907 | I26: =IF('Year-end close'!I26="","",'Year-end close'!I26/IF('Year-end close'!$C26="GBp",100,1)/INDEX('FX year-end'!$G$2:$G$11,MATCH(IF('Year-end close'!$C26="GBp","GBP",'Year-end close'!$C26),'FX year-end'!$A$2:$A$11,0))) -> 16.818681 | J26: =IF('Year-end close'!J26="","",'Year-end close'!J26/IF('Year-end close'!$C26="GBp",100,1)/INDEX('FX year-end'!$H$2:$H$11,MATCH(IF('Year-end close'!$C26="GBp","GBP",'Year-end close'!$C26),'FX year-end'!$A$2:$A$11,0))) -> 15.916869 | K26: =IF('Year-end close'!K26="","",'Year-end close'!K26/IF('Year-end close'!$C26="GBp",100,1)/INDEX('FX year-end'!$I$2:$I$11,MATCH(IF('Year-end close'!$C26="GBp","GBP",'Year-end close'!$C26),'FX year-end'!$A$2:$A$11,0))) -> 8.8298613 | L26: =IF('Year-end close'!L26="","",'Year-end close'!L26/IF('Year-end close'!$C26="GBp",100,1)/INDEX('FX year-end'!$J$2:$J$11,MATCH(IF('Year-end close'!$C26="GBp","GBP",'Year-end close'!$C26),'FX year-end'!$A$2:$A$11,0))) -> 13.140499 | M26: =IF('Year-end close'!M26="","",'Year-end close'!M26/IF('Year-end close'!$C26="GBp",100,1)/INDEX('FX year-end'!$K$2:$K$11,MATCH(IF('Year-end close'!$C26="GBp","GBP",'Year-end close'!$C26),'FX year-end'!$A$2:$A$11,0))) -> 13.651094
A28: Year-end close / year-end FX rate (pence divided by 100 first).

Sheet 2y forward
A1: ticker | B1: company | C1: currency | D1: 2019 | E1: 2020 | F1: 2021 | G1: 2022 | H1: 2023 | I1: 2024 | J1: 2025 | K1: 2026 | L1: 2027 | M1: 2028
A2: 000408.SZ | B2: Zangge Mining Co Ltd | C2: CNY | D2: =IF('Year-end close'!D2="","",'Year-end close'!D2*EXP((INDEX('Rates 2y'!$B$2:$B$11,MATCH(IF($C2="GBp","GBP",$C2),'Rates 2y'!$A$2:$A$11,0))-'Dividend yield'!D2)*2)) -> 18.35068 | E2: =IF('Year-end close'!E2="","",'Year-end close'!E2*EXP((INDEX('Rates 2y'!$C$2:$C$11,MATCH(IF($C2="GBp","GBP",$C2),'Rates 2y'!$A$2:$A$11,0))-'Dividend yield'!E2)*2)) -> 11.842537 | F2: =IF('Year-end close'!F2="","",'Year-end close'!F2*EXP((INDEX('Rates 2y'!$D$2:$D$11,MATCH(IF($C2="GBp","GBP",$C2),'Rates 2y'!$A$2:$A$11,0))-'Dividend yield'!F2)*2)) -> 7.773913 | G2: =IF('Year-end close'!G2="","",'Year-end close'!G2*EXP((INDEX('Rates 2y'!$E$2:$E$11,MATCH(IF($C2="GBp","GBP",$C2),'Rates 2y'!$A$2:$A$11,0))-'Dividend yield'!G2)*2)) -> 8.4544317 | H2: =IF('Year-end close'!H2="","",'Year-end close'!H2*EXP((INDEX('Rates 2y'!$F$2:$F$11,MATCH(IF($C2="GBp","GBP",$C2),'Rates 2y'!$A$2:$A$11,0))-'Dividend yield'!H2)*2)) -> 42.930051 | I2: =IF('Year-end close'!I2="","",'Year-end close'!I2*EXP((INDEX('Rates 2y'!$G$2:$G$11,MATCH(IF($C2="GBp","GBP",$C2),'Rates 2y'!$A$2:$A$11,0))-'Dividend yield'!I2)*2)) -> 23.49468 | J2: =IF('Year-end close'!J2="","",'Year-end close'!J2*EXP((INDEX('Rates 2y'!$H$2:$H$11,MATCH(IF($C2="GBp","GBP",$C2),'Rates 2y'!$A$2:$A$11,0))-'Dividend yield'!J2)*2)) -> 23.045584 | K2: =IF('Year-end close'!K2="","",'Year-end close'!K2*EXP((INDEX('Rates 2y'!$I$2:$I$11,MATCH(IF($C2="GBp","GBP",$C2),'Rates 2y'!$A$2:$A$11,0))-'Dividend yield'!K2)*2)) -> 26.26042 | L2: =IF('Year-end close'!L2="","",'Year-end close'!L2*EXP((INDEX('Rates 2y'!$J$2:$J$11,MATCH(IF($C2="GBp","GBP",$C2),'Rates 2y'!$A$2:$A$11,0))-'Dividend yield'!L2)*2)) -> 84.76404 | M2: =IF('Year-end close'!M2="","",'Year-end close'!M2*EXP((INDEX('Rates 2y'!$K$2:$K$11,MATCH(IF($C2="GBp","GBP",$C2),'Rates 2y'!$A$2:$A$11,0))-'Dividend yield'!M2)*2)) -> 68.52289
A3: 1208.HK | B3: MMG Ltd | C3: HKD | D3: =IF('Year-end close'!D3="","",'Year-end close'!D3*EXP((INDEX('Rates 2y'!$B$2:$B$11,MATCH(IF($C3="GBp","GBP",$C3),'Rates 2y'!$A$2:$A$11,0))-'Dividend yield'!D3)*2)) -> 3.9822029 | E3: =IF('Year-end close'!E3="","",'Year-end close'!E3*EXP((INDEX('Rates 2y'!$C$2:$C$11,MATCH(IF($C3="GBp","GBP",$C3),'Rates 2y'!$A$2:$A$11,0))-'Dividend yield'!E3)*2)) -> 3.4935302 | F3: =IF('Year-end close'!F3="","",'Year-end close'!F3*EXP((INDEX('Rates 2y'!$D$2:$D$11,MATCH(IF($C3="GBp","GBP",$C3),'Rates 2y'!$A$2:$A$11,0))-'Dividend yield'!F3)*2)) -> 2.420928 | G3: =IF('Year-end close'!G3="","",'Year-end close'!G3*EXP((INDEX('Rates 2y'!$E$2:$E$11,MATCH(IF($C3="GBp","GBP",$C3),'Rates 2y'!$A$2:$A$11,0))-'Dividend yield'!G3)*2)) -> 3.3634268 | H3: =IF('Year-end close'!H3="","",'Year-end close'!H3*EXP((INDEX('Rates 2y'!$F$2:$F$11,MATCH(IF($C3="GBp","GBP",$C3),'Rates 2y'!$A$2:$A$11,0))-'Dividend yield'!H3)*2)) -> 2.5301807 | I3: =IF('Year-end close'!I3="","",'Year-end close'!I3*EXP((INDEX('Rates 2y'!$G$2:$G$11,MATCH(IF($C3="GBp","GBP",$C3),'Rates 2y'!$A$2:$A$11,0))-'Dividend yield'!I3)*2)) -> 2.1665741 | J3: =IF('Year-end close'!J3="","",'Year-end close'!J3*EXP((INDEX('Rates 2y'!$H$2:$H$11,MATCH(IF($C3="GBp","GBP",$C3),'Rates 2y'!$A$2:$A$11,0))-'Dividend yield'!J3)*2)) -> 2.4824538 | K3: =IF('Year-end close'!K3="","",'Year-end close'!K3*EXP((INDEX('Rates 2y'!$I$2:$I$11,MATCH(IF($C3="GBp","GBP",$C3),'Rates 2y'!$A$2:$A$11,0))-'Dividend yield'!K3)*2)) -> 2.7508388 | L3: =IF('Year-end close'!L3="","",'Year-end close'!L3*EXP((INDEX('Rates 2y'!$J$2:$J$11,MATCH(IF($C3="GBp","GBP",$C3),'Rates 2y'!$A$2:$A$11,0))-'Dividend yield'!L3)*2)) -> 9.2802403 | M3: =IF('Year-end close'!M3="","",'Year-end close'!M3*EXP((INDEX('Rates 2y'!$K$2:$K$11,MATCH(IF($C3="GBp","GBP",$C3),'Rates 2y'!$A$2:$A$11,0))-'Dividend yield'!M3)*2)) -> 9.0010957
A4: 1211.SR | B4: Saudi Arabian Mining Co (Maaden) | C4: SAR | D4: =IF('Year-end close'!D4="","",'Year-end close'!D4*EXP((INDEX('Rates 2y'!$B$2:$B$11,MATCH(IF($C4="GBp","GBP",$C4),'Rates 2y'!$A$2:$A$11,0))-'Dividend yield'!D4)*2)) -> 54.226241 | E4: =IF('Year-end close'!E4="","",'Year-end close'!E4*EXP((INDEX('Rates 2y'!$C$2:$C$11,MATCH(IF($C4="GBp","GBP",$C4),'Rates 2y'!$A$2:$A$11,0))-'Dividend yield'!E4)*2)) -> 52.243949 | F4: =IF('Year-end close'!F4="","",'Year-end close'!F4*EXP((INDEX('Rates 2y'!$D$2:$D$11,MATCH(IF($C4="GBp","GBP",$C4),'Rates 2y'!$A$2:$A$11,0))-'Dividend yield'!F4)*2)) -> 46.490104 | G4: =IF('Year-end close'!G4="","",'Year-end close'!G4*EXP((INDEX('Rates 2y'!$E$2:$E$11,MATCH(IF($C4="GBp","GBP",$C4),'Rates 2y'!$A$2:$A$11,0))-'Dividend yield'!G4)*2)) -> 41.235601 | H4: =IF('Year-end close'!H4="","",'Year-end close'!H4*EXP((INDEX('Rates 2y'!$F$2:$F$11,MATCH(IF($C4="GBp","GBP",$C4),'Rates 2y'!$A$2:$A$11,0))-'Dividend yield'!H4)*2)) -> 80.40679 | I4: =IF('Year-end close'!I4="","",'Year-end close'!I4*EXP((INDEX('Rates 2y'!$G$2:$G$11,MATCH(IF($C4="GBp","GBP",$C4),'Rates 2y'!$A$2:$A$11,0))-'Dividend yield'!I4)*2)) -> 71.504558 | J4: =IF('Year-end close'!J4="","",'Year-end close'!J4*EXP((INDEX('Rates 2y'!$H$2:$H$11,MATCH(IF($C4="GBp","GBP",$C4),'Rates 2y'!$A$2:$A$11,0))-'Dividend yield'!J4)*2)) -> 54.087018 | K4: =IF('Year-end close'!K4="","",'Year-end close'!K4*EXP((INDEX('Rates 2y'!$I$2:$I$11,MATCH(IF($C4="GBp","GBP",$C4),'Rates 2y'!$A$2:$A$11,0))-'Dividend yield'!K4)*2)) -> 55.812903 | L4: =IF('Year-end close'!L4="","",'Year-end close'!L4*EXP((INDEX('Rates 2y'!$J$2:$J$11,MATCH(IF($C4="GBp","GBP",$C4),'Rates 2y'!$A$2:$A$11,0))-'Dividend yield'!L4)*2)) -> 66.823436 | M4: =IF('Year-end close'!M4="","",'Year-end close'!M4*EXP((INDEX('Rates 2y'!$K$2:$K$11,MATCH(IF($C4="GBp","GBP",$C4),'Rates 2y'!$A$2:$A$11,0))-'Dividend yield'!M4)*2)) -> 66.987891
A5: 2899.HK | B5: Zijin Mining Group Co Ltd | C5: HKD | D5: =IF('Year-end close'!D5="","",'Year-end close'!D5*EXP((INDEX('Rates 2y'!$B$2:$B$11,MATCH(IF($C5="GBp","GBP",$C5),'Rates 2y'!$A$2:$A$11,0))-'Dividend yield'!D5)*2)) -> 2.8899673 | E5: =IF('Year-end close'!E5="","",'Year-end close'!E5*EXP((INDEX('Rates 2y'!$C$2:$C$11,MATCH(IF($C5="GBp","GBP",$C5),'Rates 2y'!$A$2:$A$11,0))-'Dividend yield'!E5)*2)) -> 2.8568795 | F5: =IF('Year-end close'!F5="","",'Year-end close'!F5*EXP((INDEX('Rates 2y'!$D$2:$D$11,MATCH(IF($C5="GBp","GBP",$C5),'Rates 2y'!$A$2:$A$11,0))-'Dividend yield'!F5)*2)) -> 3.785459 | G5: =IF('Year-end close'!G5="","",'Year-end close'!G5*EXP((INDEX('Rates 2y'!$E$2:$E$11,MATCH(IF($C5="GBp","GBP",$C5),'Rates 2y'!$A$2:$A$11,0))-'Dividend yield'!G5)*2)) -> 8.5879736 | H5: =IF('Year-end close'!H5="","",'Year-end close'!H5*EXP((INDEX('Rates 2y'!$F$2:$F$11,MATCH(IF($C5="GBp","GBP",$C5),'Rates 2y'!$A$2:$A$11,0))-'Dividend yield'!H5)*2)) -> 9.1029592 | I5: =IF('Year-end close'!I5="","",'Year-end close'!I5*EXP((INDEX('Rates 2y'!$G$2:$G$11,MATCH(IF($C5="GBp","GBP",$C5),'Rates 2y'!$A$2:$A$11,0))-'Dividend yield'!I5)*2)) -> 10.968148 | J5: =IF('Year-end close'!J5="","",'Year-end close'!J5*EXP((INDEX('Rates 2y'!$H$2:$H$11,MATCH(IF($C5="GBp","GBP",$C5),'Rates 2y'!$A$2:$A$11,0))-'Dividend yield'!J5)*2)) -> 13.085641 | K5: =IF('Year-end close'!K5="","",'Year-end close'!K5*EXP((INDEX('Rates 2y'!$I$2:$I$11,MATCH(IF($C5="GBp","GBP",$C5),'Rates 2y'!$A$2:$A$11,0))-'Dividend yield'!K5)*2)) -> 14.467331 | L5: =IF('Year-end close'!L5="","",'Year-end close'!L5*EXP((INDEX('Rates 2y'!$J$2:$J$11,MATCH(IF($C5="GBp","GBP",$C5),'Rates 2y'!$A$2:$A$11,0))-'Dividend yield'!L5)*2)) -> 36.433971 | M5: =IF('Year-end close'!M5="","",'Year-end close'!M5*EXP((INDEX('Rates 2y'!$K$2:$K$11,MATCH(IF($C5="GBp","GBP",$C5),'Rates 2y'!$A$2:$A$11,0))-'Dividend yield'!M5)*2)) -> 32.348967
A6: AAL.L | B6: Anglo American plc | C6: GBp | D6: =IF('Year-end close'!D6="","",'Year-end close'!D6*EXP((INDEX('Rates 2y'!$B$2:$B$11,MATCH(IF($C6="GBp","GBP",$C6),'Rates 2y'!$A$2:$A$11,0))-'Dividend yield'!D6)*2)) -> 1479.1881 | E6: =IF('Year-end close'!E6="","",'Year-end close'!E6*EXP((INDEX('Rates 2y'!$C$2:$C$11,MATCH(IF($C6="GBp","GBP",$C6),'Rates 2y'!$A$2:$A$11,0))-'Dividend yield'!E6)*2)) -> 1602.391 | F6: =IF('Year-end close'!F6="","",'Year-end close'!F6*EXP((INDEX('Rates 2y'!$D$2:$D$11,MATCH(IF($C6="GBp","GBP",$C6),'Rates 2y'!$A$2:$A$11,0))-'Dividend yield'!F6)*2)) -> 1994.4889 | G6: =IF('Year-end close'!G6="","",'Year-end close'!G6*EXP((INDEX('Rates 2y'!$E$2:$E$11,MATCH(IF($C6="GBp","GBP",$C6),'Rates 2y'!$A$2:$A$11,0))-'Dividend yield'!G6)*2)) -> 2283.74 | H6: =IF('Year-end close'!H6="","",'Year-end close'!H6*EXP((INDEX('Rates 2y'!$F$2:$F$11,MATCH(IF($C6="GBp","GBP",$C6),'Rates 2y'!$A$2:$A$11,0))-'Dividend yield'!H6)*2)) -> 2556.5563 | I6: =IF('Year-end close'!I6="","",'Year-end close'!I6*EXP((INDEX('Rates 2y'!$G$2:$G$11,MATCH(IF($C6="GBp","GBP",$C6),'Rates 2y'!$A$2:$A$11,0))-'Dividend yield'!I6)*2)) -> 2937.3157 | J6: =IF('Year-end close'!J6="","",'Year-end close'!J6*EXP((INDEX('Rates 2y'!$H$2:$H$11,MATCH(IF($C6="GBp","GBP",$C6),'Rates 2y'!$A$2:$A$11,0))-'Dividend yield'!J6)*2)) -> 1891.3555 | K6: =IF('Year-end close'!K6="","",'Year-end close'!K6*EXP((INDEX('Rates 2y'!$I$2:$I$11,MATCH(IF($C6="GBp","GBP",$C6),'Rates 2y'!$A$2:$A$11,0))-'Dividend yield'!K6)*2)) -> 2422.5646 | L6: =IF('Year-end close'!L6="","",'Year-end close'!L6*EXP((INDEX('Rates 2y'!$J$2:$J$11,MATCH(IF($C6="GBp","GBP",$C6),'Rates 2y'!$A$2:$A$11,0))-'Dividend yield'!L6)*2)) -> 3273.8991 | M6: =IF('Year-end close'!M6="","",'Year-end close'!M6*EXP((INDEX('Rates 2y'!$K$2:$K$11,MATCH(IF($C6="GBp","GBP",$C6),'Rates 2y'!$A$2:$A$11,0))-'Dividend yield'!M6)*2)) -> 4295.1463
A7: AEM | B7: Agnico Eagle Mines Ltd | C7: USD | D7: =IF('Year-end close'!D7="","",'Year-end close'!D7*EXP((INDEX('Rates 2y'!$B$2:$B$11,MATCH(IF($C7="GBp","GBP",$C7),'Rates 2y'!$A$2:$A$11,0))-'Dividend yield'!D7)*2)) -> 47.114971 | E7: =IF('Year-end close'!E7="","",'Year-end close'!E7*EXP((INDEX('Rates 2y'!$C$2:$C$11,MATCH(IF($C7="GBp","GBP",$C7),'Rates 2y'!$A$2:$A$11,0))-'Dividend yield'!E7)*2)) -> 41.547934 | F7: =IF('Year-end close'!F7="","",'Year-end close'!F7*EXP((INDEX('Rates 2y'!$D$2:$D$11,MATCH(IF($C7="GBp","GBP",$C7),'Rates 2y'!$A$2:$A$11,0))-'Dividend yield'!F7)*2)) -> 62.462739 | G7: =IF('Year-end close'!G7="","",'Year-end close'!G7*EXP((INDEX('Rates 2y'!$E$2:$E$11,MATCH(IF($C7="GBp","GBP",$C7),'Rates 2y'!$A$2:$A$11,0))-'Dividend yield'!G7)*2)) -> 68.814092 | H7: =IF('Year-end close'!H7="","",'Year-end close'!H7*EXP((INDEX('Rates 2y'!$F$2:$F$11,MATCH(IF($C7="GBp","GBP",$C7),'Rates 2y'!$A$2:$A$11,0))-'Dividend yield'!H7)*2)) -> 51.153859 | I7: =IF('Year-end close'!I7="","",'Year-end close'!I7*EXP((INDEX('Rates 2y'!$G$2:$G$11,MATCH(IF($C7="GBp","GBP",$C7),'Rates 2y'!$A$2:$A$11,0))-'Dividend yield'!I7)*2)) -> 53.415523 | J7: =IF('Year-end close'!J7="","",'Year-end close'!J7*EXP((INDEX('Rates 2y'!$H$2:$H$11,MATCH(IF($C7="GBp","GBP",$C7),'Rates 2y'!$A$2:$A$11,0))-'Dividend yield'!J7)*2)) -> 56.331968 | K7: =IF('Year-end close'!K7="","",'Year-end close'!K7*EXP((INDEX('Rates 2y'!$I$2:$I$11,MATCH(IF($C7="GBp","GBP",$C7),'Rates 2y'!$A$2:$A$11,0))-'Dividend yield'!K7)*2)) -> 81.71859 | L7: =IF('Year-end close'!L7="","",'Year-end close'!L7*EXP((INDEX('Rates 2y'!$J$2:$J$11,MATCH(IF($C7="GBp","GBP",$C7),'Rates 2y'!$A$2:$A$11,0))-'Dividend yield'!L7)*2)) -> 178.35107 | M7: =IF('Year-end close'!M7="","",'Year-end close'!M7*EXP((INDEX('Rates 2y'!$K$2:$K$11,MATCH(IF($C7="GBp","GBP",$C7),'Rates 2y'!$A$2:$A$11,0))-'Dividend yield'!M7)*2)) -> 205.62319
A8: B | B8: Barrick Mining Corp | C8: USD | D8: =IF('Year-end close'!D8="","",'Year-end close'!D8*EXP((INDEX('Rates 2y'!$B$2:$B$11,MATCH(IF($C8="GBp","GBP",$C8),'Rates 2y'!$A$2:$A$11,0))-'Dividend yield'!D8)*2)) -> 14.780246 | E8: =IF('Year-end close'!E8="","",'Year-end close'!E8*EXP((INDEX('Rates 2y'!$C$2:$C$11,MATCH(IF($C8="GBp","GBP",$C8),'Rates 2y'!$A$2:$A$11,0))-'Dividend yield'!E8)*2)) -> 13.837527 | F8: =IF('Year-end close'!F8="","",'Year-end close'!F8*EXP((INDEX('Rates 2y'!$D$2:$D$11,MATCH(IF($C8="GBp","GBP",$C8),'Rates 2y'!$A$2:$A$11,0))-'Dividend yield'!F8)*2)) -> 18.920345 | G8: =IF('Year-end close'!G8="","",'Year-end close'!G8*EXP((INDEX('Rates 2y'!$E$2:$E$11,MATCH(IF($C8="GBp","GBP",$C8),'Rates 2y'!$A$2:$A$11,0))-'Dividend yield'!G8)*2)) -> 22.226093 | H8: =IF('Year-end close'!H8="","",'Year-end close'!H8*EXP((INDEX('Rates 2y'!$F$2:$F$11,MATCH(IF($C8="GBp","GBP",$C8),'Rates 2y'!$A$2:$A$11,0))-'Dividend yield'!H8)*2)) -> 17.75972 | I8: =IF('Year-end close'!I8="","",'Year-end close'!I8*EXP((INDEX('Rates 2y'!$G$2:$G$11,MATCH(IF($C8="GBp","GBP",$C8),'Rates 2y'!$A$2:$A$11,0))-'Dividend yield'!I8)*2)) -> 17.40358 | J8: =IF('Year-end close'!J8="","",'Year-end close'!J8*EXP((INDEX('Rates 2y'!$H$2:$H$11,MATCH(IF($C8="GBp","GBP",$C8),'Rates 2y'!$A$2:$A$11,0))-'Dividend yield'!J8)*2)) -> 18.842883 | K8: =IF('Year-end close'!K8="","",'Year-end close'!K8*EXP((INDEX('Rates 2y'!$I$2:$I$11,MATCH(IF($C8="GBp","GBP",$C8),'Rates 2y'!$A$2:$A$11,0))-'Dividend yield'!K8)*2)) -> 16.023045 | L8: =IF('Year-end close'!L8="","",'Year-end close'!L8*EXP((INDEX('Rates 2y'!$J$2:$J$11,MATCH(IF($C8="GBp","GBP",$C8),'Rates 2y'!$A$2:$A$11,0))-'Dividend yield'!L8)*2)) -> 45.57684 | M8: =IF('Year-end close'!M8="","",'Year-end close'!M8*EXP((INDEX('Rates 2y'!$K$2:$K$11,MATCH(IF($C8="GBp","GBP",$C8),'Rates 2y'!$A$2:$A$11,0))-'Dividend yield'!M8)*2)) -> 44.34906
A9: BHP.AX | B9: BHP Group Ltd | C9: AUD | D9: =IF('Year-end close'!D9="","",'Year-end close'!D9*EXP((INDEX('Rates 2y'!$B$2:$B$11,MATCH(IF($C9="GBp","GBP",$C9),'Rates 2y'!$A$2:$A$11,0))-'Dividend yield'!D9)*2)) -> 28.393009 | E9: =IF('Year-end close'!E9="","",'Year-end close'!E9*EXP((INDEX('Rates 2y'!$C$2:$C$11,MATCH(IF($C9="GBp","GBP",$C9),'Rates 2y'!$A$2:$A$11,0))-'Dividend yield'!E9)*2)) -> 32.092217 | F9: =IF('Year-end close'!F9="","",'Year-end close'!F9*EXP((INDEX('Rates 2y'!$D$2:$D$11,MATCH(IF($C9="GBp","GBP",$C9),'Rates 2y'!$A$2:$A$11,0))-'Dividend yield'!F9)*2)) -> 32.697208 | G9: =IF('Year-end close'!G9="","",'Year-end close'!G9*EXP((INDEX('Rates 2y'!$E$2:$E$11,MATCH(IF($C9="GBp","GBP",$C9),'Rates 2y'!$A$2:$A$11,0))-'Dividend yield'!G9)*2)) -> 38.755989 | H9: =IF('Year-end close'!H9="","",'Year-end close'!H9*EXP((INDEX('Rates 2y'!$F$2:$F$11,MATCH(IF($C9="GBp","GBP",$C9),'Rates 2y'!$A$2:$A$11,0))-'Dividend yield'!H9)*2)) -> 33.776085 | I9: =IF('Year-end close'!I9="","",'Year-end close'!I9*EXP((INDEX('Rates 2y'!$G$2:$G$11,MATCH(IF($C9="GBp","GBP",$C9),'Rates 2y'!$A$2:$A$11,0))-'Dividend yield'!I9)*2)) -> 39.945794 | J9: =IF('Year-end close'!J9="","",'Year-end close'!J9*EXP((INDEX('Rates 2y'!$H$2:$H$11,MATCH(IF($C9="GBp","GBP",$C9),'Rates 2y'!$A$2:$A$11,0))-'Dividend yield'!J9)*2)) -> 48.933859 | K9: =IF('Year-end close'!K9="","",'Year-end close'!K9*EXP((INDEX('Rates 2y'!$I$2:$I$11,MATCH(IF($C9="GBp","GBP",$C9),'Rates 2y'!$A$2:$A$11,0))-'Dividend yield'!K9)*2)) -> 38.206349 | L9: =IF('Year-end close'!L9="","",'Year-end close'!L9*EXP((INDEX('Rates 2y'!$J$2:$J$11,MATCH(IF($C9="GBp","GBP",$C9),'Rates 2y'!$A$2:$A$11,0))-'Dividend yield'!L9)*2)) -> 45.618007 | M9: =IF('Year-end close'!M9="","",'Year-end close'!M9*EXP((INDEX('Rates 2y'!$K$2:$K$11,MATCH(IF($C9="GBp","GBP",$C9),'Rates 2y'!$A$2:$A$11,0))-'Dividend yield'!M9)*2)) -> 60.619531
A10: EQX | B10: Equinox Gold Corp | C10: USD | D10: =IF('Year-end close'!D10="","",'Year-end close'!D10*EXP((INDEX('Rates 2y'!$B$2:$B$11,MATCH(IF($C10="GBp","GBP",$C10),'Rates 2y'!$A$2:$A$11,0))-'Dividend yield'!D10)*2)) | E10: =IF('Year-end close'!E10="","",'Year-end close'!E10*EXP((INDEX('Rates 2y'!$C$2:$C$11,MATCH(IF($C10="GBp","GBP",$C10),'Rates 2y'!$A$2:$A$11,0))-'Dividend yield'!E10)*2)) | F10: =IF('Year-end close'!F10="","",'Year-end close'!F10*EXP((INDEX('Rates 2y'!$D$2:$D$11,MATCH(IF($C10="GBp","GBP",$C10),'Rates 2y'!$A$2:$A$11,0))-'Dividend yield'!F10)*2)) -> 7.9472053 | G10: =IF('Year-end close'!G10="","",'Year-end close'!G10*EXP((INDEX('Rates 2y'!$E$2:$E$11,MATCH(IF($C10="GBp","GBP",$C10),'Rates 2y'!$A$2:$A$11,0))-'Dividend yield'!G10)*2)) -> 10.366919 | H10: =IF('Year-end close'!H10="","",'Year-end close'!H10*EXP((INDEX('Rates 2y'!$F$2:$F$11,MATCH(IF($C10="GBp","GBP",$C10),'Rates 2y'!$A$2:$A$11,0))-'Dividend yield'!H10)*2)) -> 6.85942 | I10: =IF('Year-end close'!I10="","",'Year-end close'!I10*EXP((INDEX('Rates 2y'!$G$2:$G$11,MATCH(IF($C10="GBp","GBP",$C10),'Rates 2y'!$A$2:$A$11,0))-'Dividend yield'!I10)*2)) -> 3.5838707 | J10: =IF('Year-end close'!J10="","",'Year-end close'!J10*EXP((INDEX('Rates 2y'!$H$2:$H$11,MATCH(IF($C10="GBp","GBP",$C10),'Rates 2y'!$A$2:$A$11,0))-'Dividend yield'!J10)*2)) -> 5.3238265 | K10: =IF('Year-end close'!K10="","",'Year-end close'!K10*EXP((INDEX('Rates 2y'!$I$2:$I$11,MATCH(IF($C10="GBp","GBP",$C10),'Rates 2y'!$A$2:$A$11,0))-'Dividend yield'!K10)*2)) -> 5.4642667 | L10: =IF('Year-end close'!L10="","",'Year-end close'!L10*EXP((INDEX('Rates 2y'!$J$2:$J$11,MATCH(IF($C10="GBp","GBP",$C10),'Rates 2y'!$A$2:$A$11,0))-'Dividend yield'!L10)*2)) -> 15.051993 | M10: =IF('Year-end close'!M10="","",'Year-end close'!M10*EXP((INDEX('Rates 2y'!$K$2:$K$11,MATCH(IF($C10="GBp","GBP",$C10),'Rates 2y'!$A$2:$A$11,0))-'Dividend yield'!M10)*2)) -> 12.687485
A11: EVN.AX | B11: Evolution Mining Ltd | C11: AUD | D11: =IF('Year-end close'!D11="","",'Year-end close'!D11*EXP((INDEX('Rates 2y'!$B$2:$B$11,MATCH(IF($C11="GBp","GBP",$C11),'Rates 2y'!$A$2:$A$11,0))-'Dividend yield'!D11)*2)) -> 2.6560064 | E11: =IF('Year-end close'!E11="","",'Year-end close'!E11*EXP((INDEX('Rates 2y'!$C$2:$C$11,MATCH(IF($C11="GBp","GBP",$C11),'Rates 2y'!$A$2:$A$11,0))-'Dividend yield'!E11)*2)) -> 3.6802344 | F11: =IF('Year-end close'!F11="","",'Year-end close'!F11*EXP((INDEX('Rates 2y'!$D$2:$D$11,MATCH(IF($C11="GBp","GBP",$C11),'Rates 2y'!$A$2:$A$11,0))-'Dividend yield'!F11)*2)) -> 3.680325 | G11: =IF('Year-end close'!G11="","",'Year-end close'!G11*EXP((INDEX('Rates 2y'!$E$2:$E$11,MATCH(IF($C11="GBp","GBP",$C11),'Rates 2y'!$A$2:$A$11,0))-'Dividend yield'!G11)*2)) -> 4.6894153 | H11: =IF('Year-end close'!H11="","",'Year-end close'!H11*EXP((INDEX('Rates 2y'!$F$2:$F$11,MATCH(IF($C11="GBp","GBP",$C11),'Rates 2y'!$A$2:$A$11,0))-'Dividend yield'!H11)*2)) -> 3.8731533 | I11: =IF('Year-end close'!I11="","",'Year-end close'!I11*EXP((INDEX('Rates 2y'!$G$2:$G$11,MATCH(IF($C11="GBp","GBP",$C11),'Rates 2y'!$A$2:$A$11,0))-'Dividend yield'!I11)*2)) -> 3.0699317 | J11: =IF('Year-end close'!J11="","",'Year-end close'!J11*EXP((INDEX('Rates 2y'!$H$2:$H$11,MATCH(IF($C11="GBp","GBP",$C11),'Rates 2y'!$A$2:$A$11,0))-'Dividend yield'!J11)*2)) -> 4.1788748 | K11: =IF('Year-end close'!K11="","",'Year-end close'!K11*EXP((INDEX('Rates 2y'!$I$2:$I$11,MATCH(IF($C11="GBp","GBP",$C11),'Rates 2y'!$A$2:$A$11,0))-'Dividend yield'!K11)*2)) -> 5.045976 | L11: =IF('Year-end close'!L11="","",'Year-end close'!L11*EXP((INDEX('Rates 2y'!$J$2:$J$11,MATCH(IF($C11="GBp","GBP",$C11),'Rates 2y'!$A$2:$A$11,0))-'Dividend yield'!L11)*2)) -> 13.282933 | M11: =IF('Year-end close'!M11="","",'Year-end close'!M11*EXP((INDEX('Rates 2y'!$K$2:$K$11,MATCH(IF($C11="GBp","GBP",$C11),'Rates 2y'!$A$2:$A$11,0))-'Dividend yield'!M11)*2)) -> 13.961667
A12: FCX | B12: Freeport-McMoRan Inc | C12: USD | D12: =IF('Year-end close'!D12="","",'Year-end close'!D12*EXP((INDEX('Rates 2y'!$B$2:$B$11,MATCH(IF($C12="GBp","GBP",$C12),'Rates 2y'!$A$2:$A$11,0))-'Dividend yield'!D12)*2)) -> 19.690406 | E12: =IF('Year-end close'!E12="","",'Year-end close'!E12*EXP((INDEX('Rates 2y'!$C$2:$C$11,MATCH(IF($C12="GBp","GBP",$C12),'Rates 2y'!$A$2:$A$11,0))-'Dividend yield'!E12)*2)) -> 10.525662 | F12: =IF('Year-end close'!F12="","",'Year-end close'!F12*EXP((INDEX('Rates 2y'!$D$2:$D$11,MATCH(IF($C12="GBp","GBP",$C12),'Rates 2y'!$A$2:$A$11,0))-'Dividend yield'!F12)*2)) -> 13.134598 | G12: =IF('Year-end close'!G12="","",'Year-end close'!G12*EXP((INDEX('Rates 2y'!$E$2:$E$11,MATCH(IF($C12="GBp","GBP",$C12),'Rates 2y'!$A$2:$A$11,0))-'Dividend yield'!G12)*2)) -> 25.987651 | H12: =IF('Year-end close'!H12="","",'Year-end close'!H12*EXP((INDEX('Rates 2y'!$F$2:$F$11,MATCH(IF($C12="GBp","GBP",$C12),'Rates 2y'!$A$2:$A$11,0))-'Dividend yield'!H12)*2)) -> 41.889546 | I12: =IF('Year-end close'!I12="","",'Year-end close'!I12*EXP((INDEX('Rates 2y'!$G$2:$G$11,MATCH(IF($C12="GBp","GBP",$C12),'Rates 2y'!$A$2:$A$11,0))-'Dividend yield'!I12)*2)) -> 40.229806 | J12: =IF('Year-end close'!J12="","",'Year-end close'!J12*EXP((INDEX('Rates 2y'!$H$2:$H$11,MATCH(IF($C12="GBp","GBP",$C12),'Rates 2y'!$A$2:$A$11,0))-'Dividend yield'!J12)*2)) -> 45.058506 | K12: =IF('Year-end close'!K12="","",'Year-end close'!K12*EXP((INDEX('Rates 2y'!$I$2:$I$11,MATCH(IF($C12="GBp","GBP",$C12),'Rates 2y'!$A$2:$A$11,0))-'Dividend yield'!K12)*2)) -> 40.164247 | L12: =IF('Year-end close'!L12="","",'Year-end close'!L12*EXP((INDEX('Rates 2y'!$J$2:$J$11,MATCH(IF($C12="GBp","GBP",$C12),'Rates 2y'!$A$2:$A$11,0))-'Dividend yield'!L12)*2)) -> 53.179527 | M12: =IF('Year-end close'!M12="","",'Year-end close'!M12*EXP((INDEX('Rates 2y'!$K$2:$K$11,MATCH(IF($C12="GBp","GBP",$C12),'Rates 2y'!$A$2:$A$11,0))-'Dividend yield'!M12)*2)) -> 76.563191
